Workbook

Sheet INPUTS
A1: 1300 Manhattan Ave: preliminary column sizing, inputs
A2: Blue = input. Yellow = assumption to confirm. Everything else is a formula. Loads in psf / plf / kips, lengths in ft, sections in inches.
A4: Materials and ACI 318 axial capacity
A5: f'c, concrete strength (ksi) | B5: 6 | C5: Confirm with the engineer; 6 ksi assumed for all columns
A6: fy, reinforcing steel (ksi) | B6: 60
A7: phi, tied columns (ACI 318-19 21.2.2) | B7: 0.65
A8: Maximum axial factor, tied (ACI 318-19 22.4.2.1: 0.80) | B8: 0.8
A9: Target reinforcement ratio for sizing | B9: 0.02 | C9: Section is picked so this ratio carries Pu
A10: Maximum ratio before a section is flagged NG | B10: 0.04 | C10: ACI permits 8 %; 4 % keeps splices buildable
A11: Minimum ratio (ACI 318-19 10.6.1.1) | B11: 0.01
A12: Concrete unit weight (pcf) | B12: 150
A13: Load factor, dead (ASCE 7-22 2.3.1 combination 2) | B13: 1.2
A14: Load factor, live | B14: 1.6
A15: Facade weight (plf of slab edge) | B15: 150 | C15: 15 psf of wall over a 10 ft storey; applies to the facade length the engine attributes to each column
A16: Storey height below the 1st floor slab to the footing (ft) | B16: 12 | C16: Not on the drawings received
A17: Match line x (ft, engine coordinates); columns east of it are Section B | B17: 540 | C17: The PE#1 datum sits on the match line
A18: KLL where the engine gives none (interior column, ASCE 7-22 table 4.7-1) | B18: 4
A19: Column self-weight section where the architect shows none (in2) | B19: 336 | C19: 14 x 24
A20: Garage live-load factor for columns carrying 2+ garage floors (ASCE 7-22 4.7.4) | B20: 0.8
A22: Levels and occupancies (top down). Section A = the residential bar west of the match line; Section B = the garage / amenity block east of it.
A23: Level | B23: Elev (ft) | C23: Storey below (ft) | D23: Use areas of engine floor | E23: Assumed level (1 = include) | F23: A occupancy | G23: A slab (in) | H23: A SDL (psf) | I23: A LL (psf) | J23: A LL class | K23: B occupancy | L23: B slab (in) | M23: B SDL (psf) | N23: B LL (psf) | O23: B LL class | P23: Note
A24: ROOF | B24: 201.5 | C24: =B24-B25 -> 10.5 | D24: 11 | E24: 1 | F24: none | G24: 0 | H24: 0 | I24: 0 | J24: NR | K24: roof | L24: 10 | M24: 30 | N24: 30 | O24: NR | P24: A-109 not received; Section B of the 11th stands in, roof loads
A25: 11 | B25: 191 | C25: =B25-B26 -> 11.5 | D25: 11 | E25: 0 | F25: amenity roof terrace | G25: 8 | H25: 30 | I25: 100 | J25: NR | K25: amenity / pool / fitness | L25: 10 | M25: 30 | N25: 100 | O25: NR
A26: 10 | B26: 179.5 | C26: =B26-B27 -> 10.5 | D26: 10 | E26: 0 | F26: residential | G26: 8 | H26: 20 | I26: 40 | J26: RES | K26: lobby / co-work / parking (SL1) | L26: 10 | M26: 20 | N26: 100 | O26: NR
A27: 9 | B27: 169 | C27: =B27-B28 -> 10.5 | D27: 9 | E27: 0 | F27: residential | G27: 8 | H27: 20 | I27: 40 | J27: RES | K27: parking + units | L27: 10 | M27: 5 | N27: 40 | O27: GAR
A28: 8 | B28: 158.5 | C28: =B28-B29 -> 10.5 | D28: 8 | E28: 0 | F28: residential | G28: 8 | H28: 20 | I28: 40 | J28: RES | K28: parking + units | L28: 10 | M28: 5 | N28: 40 | O28: GAR
A29: 7 | B29: 148 | C29: =B29-B30 -> 10.5 | D29: 7 | E29: 0 | F29: residential | G29: 8 | H29: 20 | I29: 40 | J29: RES | K29: parking + units | L29: 10 | M29: 5 | N29: 40 | O29: GAR
A30: 6 | B30: 137.5 | C30: =B30-B31 -> 10.5 | D30: 6 | E30: 0 | F30: residential | G30: 8 | H30: 20 | I30: 40 | J30: RES | K30: residential (3 units) | L30: 8 | M30: 20 | N30: 40 | O30: RES
A31: 5 | B31: 127 | C31: =B31-B32 -> 10.5 | D31: 5 | E31: 0 | F31: residential | G31: 8 | H31: 20 | I31: 40 | J31: RES | K31: none | L31: 8 | M31: 20 | N31: 40 | O31: RES
A32: 4 | B32: 116.5 | C32: =B32-B33 -> 10.5 | D32: 4 | E32: 0 | F32: residential | G32: 8 | H32: 20 | I32: 40 | J32: RES | K32: none | L32: 8 | M32: 20 | N32: 40 | O32: RES
A33: 3 | B33: 106 | C33: =B33-B34 -> 10.5 | D33: 4 | E33: 1 | F33: residential | G33: 8 | H33: 20 | I33: 40 | J33: RES | K33: none | L33: 8 | M33: 20 | N33: 40 | O33: RES | P33: A-107 not received; the 4th stands in
A34: 2 | B34: 95.5 | C34: =B34-B35 -> 10.5 | D34: 4 | E34: 1 | F34: residential | G34: 8 | H34: 20 | I34: 40 | J34: RES | K34: none | L34: 8 | M34: 20 | N34: 40 | O34: RES | P34: A-107 not received; the 4th stands in
A35: 1 | B35: 85 | C35: =INPUTS!$B$16 -> 12 | D35: 4 | E35: 1 | F35: residential / storage | G35: 8 | H35: 20 | I35: 40 | J35: RES | K35: none | L35: 8 | M35: 20 | N35: 40 | O35: RES | P35: A-108 not received; the 4th stands in
A37: LL class: RES = reducible per ASCE 7-22 4.7.2 (floor of 0.4 for 2+ floors, 0.5 for one); GAR = passenger garage, at most the factor above for 2+ floors; NR = not reduced (assembly, roof, L > 100 psf).
A38: Slab self-weight = thickness / 12 x unit weight. 'Assumed level' rows reuse the areas, KLL, facade and sections of the engine floor named; set the toggle to 0 to leave them out.
A40: Section families for the recommendation (smallest section whose area carries Pu at the target ratio)
A41: Family A (14 in wide, as the architect drew) | B41: Ag (in2) | D41: Family B (square, where the architect drew other shapes) | E41: Ag (in2)
A42: 14x24 | B42: 336 | D42: 18x18 | E42: 324
A43: 14x30 | B43: 420 | D43: 24x24 | E43: 576
A44: 14x36 | B44: 504 | D44: 24x30 | E44: 720
...

Sheet SUMMARY
A1: 1300 Manhattan Ave: preliminary column sizing by load takedown
A2: Preliminary. Axial load only (no moment, no slenderness, no lateral); loads and occupancies per INPUTS; tributary areas from the engine on the architect's background set 23-037A, seven floors in hand (4 to 11), floors 1 to 3 and the roof assumed. Check the yellow cells in INPUTS before quoting any number.
A4: Counts at the base of each column line
A5: Column | B5: Section | C5: Lowest level | D5: Pu at base (kips) | E5: Architect section at base | F5: Ratio it needs | G5: Status | H5: Recommended at base | I5: Floors carried | J5: Note
A6: =TRIB!A2 -> C1 | B6: =TRIB!D2 -> A | C6: =IF(COUNTIF(TRIB!$E2:$P2,">0")=0,"",INDEX(TRIB!$E$1:$P$1,SUMPRODUCT(MAX((TRIB!$E2:$P2<>"")*(COLUMN(TRIB!$E2:$P2)-COLUMN(TRIB!$E2)+1))))) -> 1 | D6: =IFERROR(INDEX(PU!$E2:$P2,MATCH(C6,TRIB!$E$1:$P$1,0)),"") -> 519.75938 | E6: =IFERROR(INDEX(ARCH!$E2:$P2,MATCH(C6,TRIB!$E$1:$P$1,0)),"") -> 14x36 | F6: =IFERROR(INDEX(RHO_ARCH!$E2:$P2,MATCH(C6,TRIB!$E$1:$P$1,0)),"") -> -0.056772152 | G6: =IFERROR(INDEX(STATUS!$E2:$P2,MATCH(C6,TRIB!$E$1:$P$1,0)),"") -> OK | H6: =IFERROR(INDEX(RECOMMEND!$E2:$P2,MATCH(C6,TRIB!$E$1:$P$1,0)),"") -> 14x24 | I6: =COUNTIF(TRIB!$E2:$P2,">0") -> 11
A7: =TRIB!A3 -> C2 | B7: =TRIB!D3 -> A | C7: =IF(COUNTIF(TRIB!$E3:$P3,">0")=0,"",INDEX(TRIB!$E$1:$P$1,SUMPRODUCT(MAX((TRIB!$E3:$P3<>"")*(COLUMN(TRIB!$E3:$P3)-COLUMN(TRIB!$E3)+1))))) -> 1 | D7: =IFERROR(INDEX(PU!$E3:$P3,MATCH(C7,TRIB!$E$1:$P$1,0)),"") -> 628.10916 | E7: =IFERROR(INDEX(ARCH!$E3:$P3,MATCH(C7,TRIB!$E$1:$P$1,0)),"") -> d24 | F7: =IFERROR(INDEX(RHO_ARCH!$E3:$P3,MATCH(C7,TRIB!$E$1:$P$1,0)),"") -> -0.044261382 | G7: =IFERROR(INDEX(STATUS!$E3:$P3,MATCH(C7,TRIB!$E$1:$P$1,0)),"") -> OK | H7: =IFERROR(INDEX(RECOMMEND!$E3:$P3,MATCH(C7,TRIB!$E$1:$P$1,0)),"") -> 18x18 | I7: =COUNTIF(TRIB!$E3:$P3,">0") -> 10
A8: =TRIB!A4 -> C3 | B8: =TRIB!D4 -> A | C8: =IF(COUNTIF(TRIB!$E4:$P4,">0")=0,"",INDEX(TRIB!$E$1:$P$1,SUMPRODUCT(MAX((TRIB!$E4:$P4<>"")*(COLUMN(TRIB!$E4:$P4)-COLUMN(TRIB!$E4)+1))))) -> 1 | D8: =IFERROR(INDEX(PU!$E4:$P4,MATCH(C8,TRIB!$E$1:$P$1,0)),"") -> 690.52547 | E8: =IFERROR(INDEX(ARCH!$E4:$P4,MATCH(C8,TRIB!$E$1:$P$1,0)),"") -> 14x36 | F8: =IFERROR(INDEX(RHO_ARCH!$E4:$P4,MATCH(C8,TRIB!$E$1:$P$1,0)),"") -> -0.044903663 | G8: =IFERROR(INDEX(STATUS!$E4:$P4,MATCH(C8,TRIB!$E$1:$P$1,0)),"") -> OK | H8: =IFERROR(INDEX(RECOMMEND!$E4:$P4,MATCH(C8,TRIB!$E$1:$P$1,0)),"") -> 14x24 | I8: =COUNTIF(TRIB!$E4:$P4,">0") -> 11
A9: =TRIB!A5 -> C4 | B9: =TRIB!D5 -> A | C9: =IF(COUNTIF(TRIB!$E5:$P5,">0")=0,"",INDEX(TRIB!$E$1:$P$1,SUMPRODUCT(MAX((TRIB!$E5:$P5<>"")*(COLUMN(TRIB!$E5:$P5)-COLUMN(TRIB!$E5)+1))))) -> 1 | D9: =IFERROR(INDEX(PU!$E5:$P5,MATCH(C9,TRIB!$E$1:$P$1,0)),"") -> 652.98904 | E9: =IFERROR(INDEX(ARCH!$E5:$P5,MATCH(C9,TRIB!$E$1:$P$1,0)),"") -> 14x24 | F9: =IFERROR(INDEX(RHO_ARCH!$E5:$P5,MATCH(C9,TRIB!$E$1:$P$1,0)),"") -> -0.024820661 | G9: =IFERROR(INDEX(STATUS!$E5:$P5,MATCH(C9,TRIB!$E$1:$P$1,0)),"") -> OK | H9: =IFERROR(INDEX(RECOMMEND!$E5:$P5,MATCH(C9,TRIB!$E$1:$P$1,0)),"") -> 14x24 | I9: =COUNTIF(TRIB!$E5:$P5,">0") -> 11
A10: =TRIB!A6 -> C5 | B10: =TRIB!D6 -> A | C10: =IF(COUNTIF(TRIB!$E6:$P6,">0")=0,"",INDEX(TRIB!$E$1:$P$1,SUMPRODUCT(MAX((TRIB!$E6:$P6<>"")*(COLUMN(TRIB!$E6:$P6)-COLUMN(TRIB!$E6)+1))))) -> 1 | D10: =IFERROR(INDEX(PU!$E6:$P6,MATCH(C10,TRIB!$E$1:$P$1,0)),"") -> 292.77054 | E10: =IFERROR(INDEX(ARCH!$E6:$P6,MATCH(C10,TRIB!$E$1:$P$1,0)),"") -> 14x24 | F10: =IFERROR(INDEX(RHO_ARCH!$E6:$P6,MATCH(C10,TRIB!$E$1:$P$1,0)),"") -> -0.062374216 | G10: =IFERROR(INDEX(STATUS!$E6:$P6,MATCH(C10,TRIB!$E$1:$P$1,0)),"") -> OK | H10: =IFERROR(INDEX(RECOMMEND!$E6:$P6,MATCH(C10,TRIB!$E$1:$P$1,0)),"") -> 14x24 | I10: =COUNTIF(TRIB!$E6:$P6,">0") -> 11
A11: =TRIB!A7 -> C6 | B11: =TRIB!D7 -> A | C11: =IF(COUNTIF(TRIB!$E7:$P7,">0")=0,"",INDEX(TRIB!$E$1:$P$1,SUMPRODUCT(MAX((TRIB!$E7:$P7<>"")*(COLUMN(TRIB!$E7:$P7)-COLUMN(TRIB!$E7)+1))))) -> 1 | D11: =IFERROR(INDEX(PU!$E7:$P7,MATCH(C11,TRIB!$E$1:$P$1,0)),"") -> 488.1797 | E11: =IFERROR(INDEX(ARCH!$E7:$P7,MATCH(C11,TRIB!$E$1:$P$1,0)),"") -> 14x24 | F11: =IFERROR(INDEX(RHO_ARCH!$E7:$P7,MATCH(C11,TRIB!$E$1:$P$1,0)),"") -> -0.04200239 | G11: =IFERROR(INDEX(STATUS!$E7:$P7,MATCH(C11,TRIB!$E$1:$P$1,0)),"") -> OK | H11: =IFERROR(INDEX(RECOMMEND!$E7:$P7,MATCH(C11,TRIB!$E$1:$P$1,0)),"") -> 14x24 | I11: =COUNTIF(TRIB!$E7:$P7,">0") -> 11
A12: =TRIB!A8 -> C7 | B12: =TRIB!D8 -> A | C12: =IF(COUNTIF(TRIB!$E8:$P8,">0")=0,"",INDEX(TRIB!$E$1:$P$1,SUMPRODUCT(MAX((TRIB!$E8:$P8<>"")*(COLUMN(TRIB!$E8:$P8)-COLUMN(TRIB!$E8)+1))))) -> 1 | D12: =IFERROR(INDEX(PU!$E8:$P8,MATCH(C12,TRIB!$E$1:$P$1,0)),"") -> 944.048 | E12: =IFERROR(INDEX(ARCH!$E8:$P8,MATCH(C12,TRIB!$E$1:$P$1,0)),"") -> 14x36 | F12: =IFERROR(INDEX(RHO_ARCH!$E8:$P8,MATCH(C12,TRIB!$E$1:$P$1,0)),"") -> -0.027283484 | G12: =IFERROR(INDEX(STATUS!$E8:$P8,MATCH(C12,TRIB!$E$1:$P$1,0)),"") -> OK | H12: =IFERROR(INDEX(RECOMMEND!$E8:$P8,MATCH(C12,TRIB!$E$1:$P$1,0)),"") -> 14x24 | I12: =COUNTIF(TRIB!$E8:$P8,">0") -> 11
A13: =TRIB!A9 -> C8 | B13: =TRIB!D9 -> A | C13: =IF(COUNTIF(TRIB!$E9:$P9,">0")=0,"",INDEX(TRIB!$E$1:$P$1,SUMPRODUCT(MAX((TRIB!$E9:$P9<>"")*(COLUMN(TRIB!$E9:$P9)-COLUMN(TRIB!$E9)+1))))) -> 1 | D13: =IFERROR(INDEX(PU!$E9:$P9,MATCH(C13,TRIB!$E$1:$P$1,0)),"") -> 955.596 | E13: =IFERROR(INDEX(ARCH!$E9:$P9,MATCH(C13,TRIB!$E$1:$P$1,0)),"") -> 14x36 | F13: =IFERROR(INDEX(RHO_ARCH!$E9:$P9,MATCH(C13,TRIB!$E$1:$P$1,0)),"") -> -0.026480881 | G13: =IFERROR(INDEX(STATUS!$E9:$P9,MATCH(C13,TRIB!$E$1:$P$1,0)),"") -> OK | H13: =IFERROR(INDEX(RECOMMEND!$E9:$P9,MATCH(C13,TRIB!$E$1:$P$1,0)),"") -> 14x24 | I13: =COUNTIF(TRIB!$E9:$P9,">0") -> 11
A14: =TRIB!A10 -> C9 | B14: =TRIB!D10 -> A | C14: =IF(COUNTIF(TRIB!$E10:$P10,">0")=0,"",INDEX(TRIB!$E$1:$P$1,SUMPRODUCT(MAX((TRIB!$E10:$P10<>"")*(COLUMN(TRIB!$E10:$P10)-COLUMN(TRIB!$E10)+1))))) -> 1 | D14: =IFERROR(INDEX(PU!$E10:$P10,MATCH(C14,TRIB!$E$1:$P$1,0)),"") -> 1015.956 | E14: =IFERROR(INDEX(ARCH!$E10:$P10,MATCH(C14,TRIB!$E$1:$P$1,0)),"") -> 14x36 | F14: =IFERROR(INDEX(RHO_ARCH!$E10:$P10,MATCH(C14,TRIB!$E$1:$P$1,0)),"") -> -0.022285774 | G14: =IFERROR(INDEX(STATUS!$E10:$P10,MATCH(C14,TRIB!$E$1:$P$1,0)),"") -> OK | H14: =IFERROR(INDEX(RECOMMEND!$E10:$P10,MATCH(C14,TRIB!$E$1:$P$1,0)),"") -> 14x24 | I14: =COUNTIF(TRIB!$E10:$P10,">0") -> 11
A15: =TRIB!A11 -> C10 | B15: =TRIB!D11 -> A | C15: =IF(COUNTIF(TRIB!$E11:$P11,">0")=0,"",INDEX(TRIB!$E$1:$P$1,SUMPRODUCT(MAX((TRIB!$E11:$P11<>"")*(COLUMN(TRIB!$E11:$P11)-COLUMN(TRIB!$E11)+1))))) -> 1 | D15: =IFERROR(INDEX(PU!$E11:$P11,MATCH(C15,TRIB!$E$1:$P$1,0)),"") -> 964.288 | E15: =IFERROR(INDEX(ARCH!$E11:$P11,MATCH(C15,TRIB!$E$1:$P$1,0)),"") -> 14x36 | F15: =IFERROR(INDEX(RHO_ARCH!$E11:$P11,MATCH(C15,TRIB!$E$1:$P$1,0)),"") -> -0.025876775 | G15: =IFERROR(INDEX(STATUS!$E11:$P11,MATCH(C15,TRIB!$E$1:$P$1,0)),"") -> OK | H15: =IFERROR(INDEX(RECOMMEND!$E11:$P11,MATCH(C15,TRIB!$E$1:$P$1,0)),"") -> 14x24 | I15: =COUNTIF(TRIB!$E11:$P11,">0") -> 11
A16: =TRIB!A12 -> C11 | B16: =TRIB!D12 -> A | C16: =IF(COUNTIF(TRIB!$E12:$P12,">0")=0,"",INDEX(TRIB!$E$1:$P$1,SUMPRODUCT(MAX((TRIB!$E12:$P12<>"")*(COLUMN(TRIB!$E12:$P12)-COLUMN(TRIB!$E12)+1))))) -> 1 | D16: =IFERROR(INDEX(PU!$E12:$P12,MATCH(C16,TRIB!$E$1:$P$1,0)),"") -> 307.64842 | E16: =IFERROR(INDEX(ARCH!$E12:$P12,MATCH(C16,TRIB!$E$1:$P$1,0)),"") -> 14x24 | F16: =IFERROR(INDEX(RHO_ARCH!$E12:$P12,MATCH(C16,TRIB!$E$1:$P$1,0)),"") -> -0.060823165 | G16: =IFERROR(INDEX(STATUS!$E12:$P12,MATCH(C16,TRIB!$E$1:$P$1,0)),"") -> OK | H16: =IFERROR(INDEX(RECOMMEND!$E12:$P12,MATCH(C16,TRIB!$E$1:$P$1,0)),"") -> 14x24 | I16: =COUNTIF(TRIB!$E12:$P12,">0") -> 11
A17: =TRIB!A13 -> C12 | B17: =TRIB!D13 -> A | C17: =IF(COUNTIF(TRIB!$E13:$P13,">0")=0,"",INDEX(TRIB!$E$1:$P$1,SUMPRODUCT(MAX((TRIB!$E13:$P13<>"")*(COLUMN(TRIB!$E13:$P13)-COLUMN(TRIB!$E13)+1))))) -> 1 | D17: =IFERROR(INDEX(PU!$E13:$P13,MATCH(C17,TRIB!$E$1:$P$1,0)),"") -> 1028.028 | E17: =IFERROR(INDEX(ARCH!$E13:$P13,MATCH(C17,TRIB!$E$1:$P$1,0)),"") -> 14x36 | F17: =IFERROR(INDEX(RHO_ARCH!$E13:$P13,MATCH(C17,TRIB!$E$1:$P$1,0)),"") -> -0.021446753 | G17: =IFERROR(INDEX(STATUS!$E13:$P13,MATCH(C17,TRIB!$E$1:$P$1,0)),"") -> OK | H17: =IFERROR(INDEX(RECOMMEND!$E13:$P13,MATCH(C17,TRIB!$E$1:$P$1,0)),"") -> 14x24 | I17: =COUNTIF(TRIB!$E13:$P13,">0") -> 11
... A122: =TRIB!A118 -> C117 | B122: =TRIB!D118 -> B | C122: =IF(COUNTIF(TRIB!$E118:$P118,">0")=0,"",INDEX(TRIB!$E$1:$P$1,SUMPRODUCT(MAX((TRIB!$E118:$P118<>"")*(COLUMN(TRIB!$E118:$P118)-COLUMN(TRIB!$E118)+1))))) -> 11 | D122: =IFERROR(INDEX(PU!$E118:$P118,MATCH(C122,TRIB!$E$1:$P$1,0)),"") -> 149.58 | E122: =IFERROR(INDEX(ARCH!$E118:$P118,MATCH(C122,TRIB!$E$1:$P$1,0)),"") -> 14x36 | F122: =IFERROR(INDEX(RHO_ARCH!$E118:$P118,MATCH(C122,TRIB!$E$1:$P$1,0)),"") -> -0.08250015 | G122: =IFERROR(INDEX(STATUS!$E118:$P118,MATCH(C122,TRIB!$E$1:$P$1,0)),"") -> OK | H122: =IFERROR(INDEX(RECOMMEND!$E118:$P118,MATCH(C122,TRIB!$E$1:$P$1,0)),"") -> 14x24 | I122: =COUNTIF(TRIB!$E118:$P118,">0") -> 2
A123: =TRIB!A119 -> 7_UNLABELED_100 | B123: =TRIB!D119 -> A | C123: =IF(COUNTIF(TRIB!$E119:$P119,">0")=0,"",INDEX(TRIB!$E$1:$P$1,SUMPRODUCT(MAX((TRIB!$E119:$P119<>"")*(COLUMN(TRIB!$E119:$P119)-COLUMN(TRIB!$E119)+1))))) | D123: =IFERROR(INDEX(PU!$E119:$P119,MATCH(C123,TRIB!$E$1:$P$1,0)),"") | E123: =IFERROR(INDEX(ARCH!$E119:$P119,MATCH(C123,TRIB!$E$1:$P$1,0)),"") | F123: =IFERROR(INDEX(RHO_ARCH!$E119:$P119,MATCH(C123,TRIB!$E$1:$P$1,0)),"") | G123: =IFERROR(INDEX(STATUS!$E119:$P119,MATCH(C123,TRIB!$E$1:$P$1,0)),"") | H123: =IFERROR(INDEX(RECOMMEND!$E119:$P119,MATCH(C123,TRIB!$E$1:$P$1,0)),"") | I123: =COUNTIF(TRIB!$E119:$P119,">0") -> 0 | J123: Outside the draft slab on the 7th east bay; carries only that level in this takedown
A124: =TRIB!A120 -> 7_UNLABELED_101 | B124: =TRIB!D120 -> A | C124: =IF(COUNTIF(TRIB!$E120:$P120,">0")=0,"",INDEX(TRIB!$E$1:$P$1,SUMPRODUCT(MAX((TRIB!$E120:$P120<>"")*(COLUMN(TRIB!$E120:$P120)-COLUMN(TRIB!$E120)+1))))) -> 7 | D124: =IFERROR(INDEX(PU!$E120:$P120,MATCH(C124,TRIB!$E$1:$P$1,0)),"") -> 24.179 | E124: =IFERROR(INDEX(ARCH!$E120:$P120,MATCH(C124,TRIB!$E$1:$P$1,0)),"") -> 14x36 | F124: =IFERROR(INDEX(RHO_ARCH!$E120:$P120,MATCH(C124,TRIB!$E$1:$P$1,0)),"") -> -0.0912157 | G124: =IFERROR(INDEX(STATUS!$E120:$P120,MATCH(C124,TRIB!$E$1:$P$1,0)),"") -> OK | H124: =IFERROR(INDEX(RECOMMEND!$E120:$P120,MATCH(C124,TRIB!$E$1:$P$1,0)),"") -> 14x24 | I124: =COUNTIF(TRIB!$E120:$P120,">0") -> 1 | J124: Outside the draft slab on the 7th east bay; carries only that level in this takedown
A125: =TRIB!A121 -> 7_UNLABELED_102 | B125: =TRIB!D121 -> A | C125: =IF(COUNTIF(TRIB!$E121:$P121,">0")=0,"",INDEX(TRIB!$E$1:$P$1,SUMPRODUCT(MAX((TRIB!$E121:$P121<>"")*(COLUMN(TRIB!$E121:$P121)-COLUMN(TRIB!$E121)+1))))) | D125: =IFERROR(INDEX(PU!$E121:$P121,MATCH(C125,TRIB!$E$1:$P$1,0)),"") | E125: =IFERROR(INDEX(ARCH!$E121:$P121,MATCH(C125,TRIB!$E$1:$P$1,0)),"") | F125: =IFERROR(INDEX(RHO_ARCH!$E121:$P121,MATCH(C125,TRIB!$E$1:$P$1,0)),"") | G125: =IFERROR(INDEX(STATUS!$E121:$P121,MATCH(C125,TRIB!$E$1:$P$1,0)),"") | H125: =IFERROR(INDEX(RECOMMEND!$E121:$P121,MATCH(C125,TRIB!$E$1:$P$1,0)),"") | I125: =COUNTIF(TRIB!$E121:$P121,">0") -> 0 | J125: Outside the draft slab on the 7th east bay; carries only that level in this takedown
A126: =TRIB!A122 -> 7_UNLABELED_103 | B126: =TRIB!D122 -> A | C126: =IF(COUNTIF(TRIB!$E122:$P122,">0")=0,"",INDEX(TRIB!$E$1:$P$1,SUMPRODUCT(MAX((TRIB!$E122:$P122<>"")*(COLUMN(TRIB!$E122:$P122)-COLUMN(TRIB!$E122)+1))))) | D126: =IFERROR(INDEX(PU!$E122:$P122,MATCH(C126,TRIB!$E$1:$P$1,0)),"") | E126: =IFERROR(INDEX(ARCH!$E122:$P122,MATCH(C126,TRIB!$E$1:$P$1,0)),"") | F126: =IFERROR(INDEX(RHO_ARCH!$E122:$P122,MATCH(C126,TRIB!$E$1:$P$1,0)),"") | G126: =IFERROR(INDEX(STATUS!$E122:$P122,MATCH(C126,TRIB!$E$1:$P$1,0)),"") | H126: =IFERROR(INDEX(RECOMMEND!$E122:$P122,MATCH(C126,TRIB!$E$1:$P$1,0)),"") | I126: =COUNTIF(TRIB!$E122:$P122,">0") -> 0 | J126: Outside the draft slab on the 7th east bay; carries only that level in this takedown
A127: =TRIB!A123 -> 7_UNLABELED_90 | B127: =TRIB!D123 -> A | C127: =IF(COUNTIF(TRIB!$E123:$P123,">0")=0,"",INDEX(TRIB!$E$1:$P$1,SUMPRODUCT(MAX((TRIB!$E123:$P123<>"")*(COLUMN(TRIB!$E123:$P123)-COLUMN(TRIB!$E123)+1))))) | D127: =IFERROR(INDEX(PU!$E123:$P123,MATCH(C127,TRIB!$E$1:$P$1,0)),"") | E127: =IFERROR(INDEX(ARCH!$E123:$P123,MATCH(C127,TRIB!$E$1:$P$1,0)),"") | F127: =IFERROR(INDEX(RHO_ARCH!$E123:$P123,MATCH(C127,TRIB!$E$1:$P$1,0)),"") | G127: =IFERROR(INDEX(STATUS!$E123:$P123,MATCH(C127,TRIB!$E$1:$P$1,0)),"") | H127: =IFERROR(INDEX(RECOMMEND!$E123:$P123,MATCH(C127,TRIB!$E$1:$P$1,0)),"") | I127: =COUNTIF(TRIB!$E123:$P123,">0") -> 0 | J127: Outside the draft slab on the 7th east bay; carries only that level in this takedown
A128: =TRIB!A124 -> 7_UNLABELED_91 | B128: =TRIB!D124 -> A | C128: =IF(COUNTIF(TRIB!$E124:$P124,">0")=0,"",INDEX(TRIB!$E$1:$P$1,SUMPRODUCT(MAX((TRIB!$E124:$P124<>"")*(COLUMN(TRIB!$E124:$P124)-COLUMN(TRIB!$E124)+1))))) -> 7 | D128: =IFERROR(INDEX(PU!$E124:$P124,MATCH(C128,TRIB!$E$1:$P$1,0)),"") -> 41.533339 | E128: =IFERROR(INDEX(ARCH!$E124:$P124,MATCH(C128,TRIB!$E$1:$P$1,0)),"") -> 14x36 | F128: =IFERROR(INDEX(RHO_ARCH!$E124:$P124,MATCH(C128,TRIB!$E$1:$P$1,0)),"") -> -0.090009548 | G128: =IFERROR(INDEX(STATUS!$E124:$P124,MATCH(C128,TRIB!$E$1:$P$1,0)),"") -> OK | H128: =IFERROR(INDEX(RECOMMEND!$E124:$P124,MATCH(C128,TRIB!$E$1:$P$1,0)),"") -> 14x24 | I128: =COUNTIF(TRIB!$E124:$P124,">0") -> 1 | J128: Outside the draft slab on the 7th east bay; carries only that level in this takedown
A129: =TRIB!A125 -> 7_UNLABELED_92 | B129: =TRIB!D125 -> A | C129: =IF(COUNTIF(TRIB!$E125:$P125,">0")=0,"",INDEX(TRIB!$E$1:$P$1,SUMPRODUCT(MAX((TRIB!$E125:$P125<>"")*(COLUMN(TRIB!$E125:$P125)-COLUMN(TRIB!$E125)+1))))) | D129: =IFERROR(INDEX(PU!$E125:$P125,MATCH(C129,TRIB!$E$1:$P$1,0)),"") | E129: =IFERROR(INDEX(ARCH!$E125:$P125,MATCH(C129,TRIB!$E$1:$P$1,0)),"") | F129: =IFERROR(INDEX(RHO_ARCH!$E125:$P125,MATCH(C129,TRIB!$E$1:$P$1,0)),"") | G129: =IFERROR(INDEX(STATUS!$E125:$P125,MATCH(C129,TRIB!$E$1:$P$1,0)),"") | H129: =IFERROR(INDEX(RECOMMEND!$E125:$P125,MATCH(C129,TRIB!$E$1:$P$1,0)),"") | I129: =COUNTIF(TRIB!$E125:$P125,">0") -> 0 | J129: Outside the draft slab on the 7th east bay; carries only that level in this takedown
A130: =TRIB!A126 -> 7_UNLABELED_93 | B130: =TRIB!D126 -> A | C130: =IF(COUNTIF(TRIB!$E126:$P126,">0")=0,"",INDEX(TRIB!$E$1:$P$1,SUMPRODUCT(MAX((TRIB!$E126:$P126<>"")*(COLUMN(TRIB!$E126:$P126)-COLUMN(TRIB!$E126)+1))))) | D130: =IFERROR(INDEX(PU!$E126:$P126,MATCH(C130,TRIB!$E$1:$P$1,0)),"") | E130: =IFERROR(INDEX(ARCH!$E126:$P126,MATCH(C130,TRIB!$E$1:$P$1,0)),"") | F130: =IFERROR(INDEX(RHO_ARCH!$E126:$P126,MATCH(C130,TRIB!$E$1:$P$1,0)),"") | G130: =IFERROR(INDEX(STATUS!$E126:$P126,MATCH(C130,TRIB!$E$1:$P$1,0)),"") | H130: =IFERROR(INDEX(RECOMMEND!$E126:$P126,MATCH(C130,TRIB!$E$1:$P$1,0)),"") | I130: =COUNTIF(TRIB!$E126:$P126,">0") -> 0 | J130: Outside the draft slab on the 7th east bay; carries only that level in this takedown
A131: =TRIB!A127 -> 7_UNLABELED_94 | B131: =TRIB!D127 -> A | C131: =IF(COUNTIF(TRIB!$E127:$P127,">0")=0,"",INDEX(TRIB!$E$1:$P$1,SUMPRODUCT(MAX((TRIB!$E127:$P127<>"")*(COLUMN(TRIB!$E127:$P127)-COLUMN(TRIB!$E127)+1))))) -> 7 | D131: =IFERROR(INDEX(PU!$E127:$P127,MATCH(C131,TRIB!$E$1:$P$1,0)),"") -> 28.879 | E131: =IFERROR(INDEX(ARCH!$E127:$P127,MATCH(C131,TRIB!$E$1:$P$1,0)),"") -> 14x36 | F131: =IFERROR(INDEX(RHO_ARCH!$E127:$P127,MATCH(C131,TRIB!$E$1:$P$1,0)),"") -> -0.090889043 | G131: =IFERROR(INDEX(STATUS!$E127:$P127,MATCH(C131,TRIB!$E$1:$P$1,0)),"") -> OK | H131: =IFERROR(INDEX(RECOMMEND!$E127:$P127,MATCH(C131,TRIB!$E$1:$P$1,0)),"") -> 14x24 | I131: =COUNTIF(TRIB!$E127:$P127,">0") -> 1 | J131: Outside the draft slab on the 7th east bay; carries only that level in this takedown
A132: =TRIB!A128 -> 7_UNLABELED_95 | B132: =TRIB!D128 -> A | C132: =IF(COUNTIF(TRIB!$E128:$P128,">0")=0,"",INDEX(TRIB!$E$1:$P$1,SUMPRODUCT(MAX((TRIB!$E128:$P128<>"")*(COLUMN(TRIB!$E128:$P128)-COLUMN(TRIB!$E128)+1))))) | D132: =IFERROR(INDEX(PU!$E128:$P128,MATCH(C132,TRIB!$E$1:$P$1,0)),"") | E132: =IFERROR(INDEX(ARCH!$E128:$P128,MATCH(C132,TRIB!$E$1:$P$1,0)),"") | F132: =IFERROR(INDEX(RHO_ARCH!$E128:$P128,MATCH(C132,TRIB!$E$1:$P$1,0)),"") | G132: =IFERROR(INDEX(STATUS!$E128:$P128,MATCH(C132,TRIB!$E$1:$P$1,0)),"") | H132: =IFERROR(INDEX(RECOMMEND!$E128:$P128,MATCH(C132,TRIB!$E$1:$P$1,0)),"") | I132: =COUNTIF(TRIB!$E128:$P128,">0") -> 0 | J132: Outside the draft slab on the 7th east bay; carries only that level in this takedown
A133: =TRIB!A129 -> 7_UNLABELED_96 | B133: =TRIB!D129 -> A | C133: =IF(COUNTIF(TRIB!$E129:$P129,">0")=0,"",INDEX(TRIB!$E$1:$P$1,SUMPRODUCT(MAX((TRIB!$E129:$P129<>"")*(COLUMN(TRIB!$E129:$P129)-COLUMN(TRIB!$E129)+1))))) | D133: =IFERROR(INDEX(PU!$E129:$P129,MATCH(C133,TRIB!$E$1:$P$1,0)),"") | E133: =IFERROR(INDEX(ARCH!$E129:$P129,MATCH(C133,TRIB!$E$1:$P$1,0)),"") | F133: =IFERROR(INDEX(RHO_ARCH!$E129:$P129,MATCH(C133,TRIB!$E$1:$P$1,0)),"") | G133: =IFERROR(INDEX(STATUS!$E129:$P129,MATCH(C133,TRIB!$E$1:$P$1,0)),"") | H133: =IFERROR(INDEX(RECOMMEND!$E129:$P129,MATCH(C133,TRIB!$E$1:$P$1,0)),"") | I133: =COUNTIF(TRIB!$E129:$P129,">0") -> 0 | J133: Outside the draft slab on the 7th east bay; carries only that level in this takedown
A134: =TRIB!A130 -> 7_UNLABELED_97 | B134: =TRIB!D130 -> A | C134: =IF(COUNTIF(TRIB!$E130:$P130,">0")=0,"",INDEX(TRIB!$E$1:$P$1,SUMPRODUCT(MAX((TRIB!$E130:$P130<>"")*(COLUMN(TRIB!$E130:$P130)-COLUMN(TRIB!$E130)+1))))) -> 7 | D134: =IFERROR(INDEX(PU!$E130:$P130,MATCH(C134,TRIB!$E$1:$P$1,0)),"") -> 37.918458 | E134: =IFERROR(INDEX(ARCH!$E130:$P130,MATCH(C134,TRIB!$E$1:$P$1,0)),"") -> 14x36 | F134: =IFERROR(INDEX(RHO_ARCH!$E130:$P130,MATCH(C134,TRIB!$E$1:$P$1,0)),"") -> -0.090260788 | G134: =IFERROR(INDEX(STATUS!$E130:$P130,MATCH(C134,TRIB!$E$1:$P$1,0)),"") -> OK | H134: =IFERROR(INDEX(RECOMMEND!$E130:$P130,MATCH(C134,TRIB!$E$1:$P$1,0)),"") -> 14x24 | I134: =COUNTIF(TRIB!$E130:$P130,">0") -> 1 | J134: Outside the draft slab on the 7th east bay; carries only that level in this takedown
... A138: =TRIB!A134 -> 8_UNLABELED_107 | B138: =TRIB!D134 -> A | C138: =IF(COUNTIF(TRIB!$E134:$P134,">0")=0,"",INDEX(TRIB!$E$1:$P$1,SUMPRODUCT(MAX((TRIB!$E134:$P134<>"")*(COLUMN(TRIB!$E134:$P134)-COLUMN(TRIB!$E134)+1))))) -> 8 | D138: =IFERROR(INDEX(PU!$E134:$P134,MATCH(C138,TRIB!$E$1:$P$1,0)),"") -> 31.787 | E138: =IFERROR(INDEX(ARCH!$E134:$P134,MATCH(C138,TRIB!$E$1:$P$1,0)),"") -> 14x36 | F138: =IFERROR(INDEX(RHO_ARCH!$E134:$P134,MATCH(C138,TRIB!$E$1:$P$1,0)),"") -> -0.090686933 | G138: =IFERROR(INDEX(STATUS!$E134:$P134,MATCH(C138,TRIB!$E$1:$P$1,0)),"") -> OK | H138: =IFERROR(INDEX(RECOMMEND!$E134:$P134,MATCH(C138,TRIB!$E$1:$P$1,0)),"") -> 14x24 | I138: =COUNTIF(TRIB!$E134:$P134,">0") -> 1 | J138: Outside the draft slab on the 7th east bay; carries only that level in this takedown
A140: Status counts at the base
A141: OK | B141: =COUNTIF($G$6:$G$138,"OK") -> 122
A142: HEAVY | B142: =COUNTIF($G$6:$G$138,"HEAVY") -> 1
A143: NG | B143: =COUNTIF($G$6:$G$138,"NG") -> 0
A145: Recommended section counts per level (how many columns the scheme needs at each size)
A146: Section | B146: ROOF | C146: 11 | D146: 10 | E146: 9 | F146: 8 | G146: 7 | H146: 6 | I146: 5 | J146: 4 | K146: 3 | L146: 2 | M146: 1
A147: 14x24 | B147: =COUNTIF(RECOMMEND!E$2:E$134,$A147) -> 64 | C147: =COUNTIF(RECOMMEND!F$2:F$134,$A147) -> 113 | D147: =COUNTIF(RECOMMEND!G$2:G$134,$A147) -> 108 | E147: =COUNTIF(RECOMMEND!H$2:H$134,$A147) -> 106 | F147: =COUNTIF(RECOMMEND!I$2:I$134,$A147) -> 106 | G147: =COUNTIF(RECOMMEND!J$2:J$134,$A147) -> 103 | H147: =COUNTIF(RECOMMEND!K$2:K$134,$A147) -> 60 | I147: =COUNTIF(RECOMMEND!L$2:L$134,$A147) -> 60 | ... M147: =COUNTIF(RECOMMEND!P$2:P$134,$A147) -> 55
A148: 14x30 | B148: =COUNTIF(RECOMMEND!E$2:E$134,$A148) -> 0 | C148: =COUNTIF(RECOMMEND!F$2:F$134,$A148) -> 0 | D148: =COUNTIF(RECOMMEND!G$2:G$134,$A148) -> 0 | E148: =COUNTIF(RECOMMEND!H$2:H$134,$A148) -> 0 | F148: =COUNTIF(RECOMMEND!I$2:I$134,$A148) -> 0 | G148: =COUNTIF(RECOMMEND!J$2:J$134,$A148) -> 0 | H148: =COUNTIF(RECOMMEND!K$2:K$134,$A148) -> 0 | I148: =COUNTIF(RECOMMEND!L$2:L$134,$A148) -> 0 | ... M148: =COUNTIF(RECOMMEND!P$2:P$134,$A148) -> 5
A149: 14x36 | B149: =COUNTIF(RECOMMEND!E$2:E$134,$A149) -> 0 | C149: =COUNTIF(RECOMMEND!F$2:F$134,$A149) -> 0 | D149: =COUNTIF(RECOMMEND!G$2:G$134,$A149) -> 0 | E149: =COUNTIF(RECOMMEND!H$2:H$134,$A149) -> 0 | F149: =COUNTIF(RECOMMEND!I$2:I$134,$A149) -> 0 | G149: =COUNTIF(RECOMMEND!J$2:J$134,$A149) -> 0 | H149: =COUNTIF(RECOMMEND!K$2:K$134,$A149) -> 0 | I149: =COUNTIF(RECOMMEND!L$2:L$134,$A149) -> 0 | ... M149: =COUNTIF(RECOMMEND!P$2:P$134,$A149) -> 0
A150: 14x42 | B150: =COUNTIF(RECOMMEND!E$2:E$134,$A150) -> 0 | C150: =COUNTIF(RECOMMEND!F$2:F$134,$A150) -> 0 | D150: =COUNTIF(RECOMMEND!G$2:G$134,$A150) -> 0 | E150: =COUNTIF(RECOMMEND!H$2:H$134,$A150) -> 0 | F150: =COUNTIF(RECOMMEND!I$2:I$134,$A150) -> 0 | G150: =COUNTIF(RECOMMEND!J$2:J$134,$A150) -> 0 | H150: =COUNTIF(RECOMMEND!K$2:K$134,$A150) -> 0 | I150: =COUNTIF(RECOMMEND!L$2:L$134,$A150) -> 0 | ... M150: =COUNTIF(RECOMMEND!P$2:P$134,$A150) -> 0
...

Sheet TRIB
A1: Column | B1: x (ft) | C1: y (ft) | D1: Section | E1: ROOF | F1: 11 | G1: 10 | H1: 9 | I1: 8 | J1: 7 | K1: 6 | L1: 5 | M1: 4 | N1: 3 | O1: 2 | P1: 1 | R1: Tributary slab area (sf) per column per level, from the engine's takedown (Voronoi with walls). Assumed levels reuse an engine floor times the INPUTS toggle; ROOF uses Section B only.
A2: C1 | B2: 283.70052 | C2: 569.16697 | D2: =IF(B2="","A",IF(B2>=INPUTS!$B$17,"B","A")) -> A | E2: =IF(AND(INPUTS!$E$24=1,$D2="B",TRIB!F2<>""),TRIB!F2,"") | F2: 328 | G2: 163 | H2: 162 | I2: 162 | J2: 163 | K2: 154 | L2: 154 | M2: 154 | N2: =IF(AND(INPUTS!$E$33=1,TRIB!M2<>""),TRIB!M2,"") -> 154 | O2: =IF(AND(INPUTS!$E$34=1,TRIB!M2<>""),TRIB!M2,"") -> 154 | P2: =IF(AND(INPUTS!$E$35=1,TRIB!M2<>""),TRIB!M2,"") -> 154
A3: C2 | B3: 283.56914 | C3: 554.06436 | D3: =IF(B3="","A",IF(B3>=INPUTS!$B$17,"B","A")) -> A | E3: =IF(AND(INPUTS!$E$24=1,$D3="B",TRIB!F3<>""),TRIB!F3,"") | G3: 300 | H3: 299 | I3: 299 | J3: 299 | K3: 299 | L3: 299 | M3: 299 | N3: =IF(AND(INPUTS!$E$33=1,TRIB!M3<>""),TRIB!M3,"") -> 299 | O3: =IF(AND(INPUTS!$E$34=1,TRIB!M3<>""),TRIB!M3,"") -> 299 | P3: =IF(AND(INPUTS!$E$35=1,TRIB!M3<>""),TRIB!M3,"") -> 299
A4: C3 | B4: 302.32736 | C4: 538.83473 | D4: =IF(B4="","A",IF(B4>=INPUTS!$B$17,"B","A")) -> A | E4: =IF(AND(INPUTS!$E$24=1,$D4="B",TRIB!F4<>""),TRIB!F4,"") | F4: 294 | G4: 287 | H4: 275 | I4: 275 | J4: 275 | K4: 275 | L4: 277 | M4: 277 | N4: =IF(AND(INPUTS!$E$33=1,TRIB!M4<>""),TRIB!M4,"") -> 277 | O4: =IF(AND(INPUTS!$E$34=1,TRIB!M4<>""),TRIB!M4,"") -> 277 | P4: =IF(AND(INPUTS!$E$35=1,TRIB!M4<>""),TRIB!M4,"") -> 277
A5: C4 | B5: 301.5302 | C5: 560.06227 | D5: =IF(B5="","A",IF(B5>=INPUTS!$B$17,"B","A")) -> A | E5: =IF(AND(INPUTS!$E$24=1,$D5="B",TRIB!F5<>""),TRIB!F5,"") | F5: 351 | G5: 282 | H5: 282 | I5: 282 | J5: 282 | K5: 282 | L5: 282 | M5: 282 | N5: =IF(AND(INPUTS!$E$33=1,TRIB!M5<>""),TRIB!M5,"") -> 282 | O5: =IF(AND(INPUTS!$E$34=1,TRIB!M5<>""),TRIB!M5,"") -> 282 | P5: =IF(AND(INPUTS!$E$35=1,TRIB!M5<>""),TRIB!M5,"") -> 282
A6: C5 | B6: 311.63942 | C6: 569.16697 | D6: =IF(B6="","A",IF(B6>=INPUTS!$B$17,"B","A")) -> A | E6: =IF(AND(INPUTS!$E$24=1,$D6="B",TRIB!F6<>""),TRIB!F6,"") | F6: 96 | G6: 104 | H6: 104 | I6: 104 | J6: 104 | K6: 99 | L6: 99 | M6: 99 | N6: =IF(AND(INPUTS!$E$33=1,TRIB!M6<>""),TRIB!M6,"") -> 99 | O6: =IF(AND(INPUTS!$E$34=1,TRIB!M6<>""),TRIB!M6,"") -> 99 | P6: =IF(AND(INPUTS!$E$35=1,TRIB!M6<>""),TRIB!M6,"") -> 99
A7: C6 | B7: 313.93295 | C7: 553.64886 | D7: =IF(B7="","A",IF(B7>=INPUTS!$B$17,"B","A")) -> A | E7: =IF(AND(INPUTS!$E$24=1,$D7="B",TRIB!F7<>""),TRIB!F7,"") | F7: 216 | G7: 216 | H7: 216 | I7: 216 | J7: 216 | K7: 215 | L7: 215 | M7: 215 | N7: =IF(AND(INPUTS!$E$33=1,TRIB!M7<>""),TRIB!M7,"") -> 215 | O7: =IF(AND(INPUTS!$E$34=1,TRIB!M7<>""),TRIB!M7,"") -> 215 | P7: =IF(AND(INPUTS!$E$35=1,TRIB!M7<>""),TRIB!M7,"") -> 215
A8: C7 | B8: 336.33509 | C8: 514.66264 | D8: =IF(B8="","A",IF(B8>=INPUTS!$B$17,"B","A")) -> A | E8: =IF(AND(INPUTS!$E$24=1,$D8="B",TRIB!F8<>""),TRIB!F8,"") | F8: 381 | G8: 407 | H8: 407 | I8: 407 | J8: 407 | K8: 407 | L8: 407 | M8: 407 | N8: =IF(AND(INPUTS!$E$33=1,TRIB!M8<>""),TRIB!M8,"") -> 407 | O8: =IF(AND(INPUTS!$E$34=1,TRIB!M8<>""),TRIB!M8,"") -> 407 | P8: =IF(AND(INPUTS!$E$35=1,TRIB!M8<>""),TRIB!M8,"") -> 407
A9: C8 | B9: 346.65209 | C9: 529.37224 | D9: =IF(B9="","A",IF(B9>=INPUTS!$B$17,"B","A")) -> A | E9: =IF(AND(INPUTS!$E$24=1,$D9="B",TRIB!F9<>""),TRIB!F9,"") | F9: 438 | G9: 438 | H9: 438 | I9: 438 | J9: 438 | K9: 438 | L9: 438 | M9: 438 | N9: =IF(AND(INPUTS!$E$33=1,TRIB!M9<>""),TRIB!M9,"") -> 438 | O9: =IF(AND(INPUTS!$E$34=1,TRIB!M9<>""),TRIB!M9,"") -> 438 | P9: =IF(AND(INPUTS!$E$35=1,TRIB!M9<>""),TRIB!M9,"") -> 438
A10: C9 | B10: 356.10812 | C10: 546.09305 | D10: =IF(B10="","A",IF(B10>=INPUTS!$B$17,"B","A")) -> A | E10: =IF(AND(INPUTS!$E$24=1,$D10="B",TRIB!F10<>""),TRIB!F10,"") | F10: 468 | G10: 468 | H10: 468 | I10: 468 | J10: 468 | K10: 468 | L10: 468 | M10: 468 | N10: =IF(AND(INPUTS!$E$33=1,TRIB!M10<>""),TRIB!M10,"") -> 468 | O10: =IF(AND(INPUTS!$E$34=1,TRIB!M10<>""),TRIB!M10,"") -> 468 | P10: =IF(AND(INPUTS!$E$35=1,TRIB!M10<>""),TRIB!M10,"") -> 468
A11: C10 | B11: 357.42596 | C11: 500.43849 | D11: =IF(B11="","A",IF(B11>=INPUTS!$B$17,"B","A")) -> A | E11: =IF(AND(INPUTS!$E$24=1,$D11="B",TRIB!F11<>""),TRIB!F11,"") | F11: 390 | G11: 418 | H11: 418 | I11: 418 | J11: 418 | K11: 418 | L11: 418 | M11: 418 | N11: =IF(AND(INPUTS!$E$33=1,TRIB!M11<>""),TRIB!M11,"") -> 418 | O11: =IF(AND(INPUTS!$E$34=1,TRIB!M11<>""),TRIB!M11,"") -> 418 | P11: =IF(AND(INPUTS!$E$35=1,TRIB!M11<>""),TRIB!M11,"") -> 418
A12: C11 | B12: 363.12676 | C12: 569.16697 | D12: =IF(B12="","A",IF(B12>=INPUTS!$B$17,"B","A")) -> A | E12: =IF(AND(INPUTS!$E$24=1,$D12="B",TRIB!F12<>""),TRIB!F12,"") | F12: 115 | G12: 115 | H12: 115 | I12: 115 | J12: 115 | K12: 104 | L12: 104 | M12: 104 | N12: =IF(AND(INPUTS!$E$33=1,TRIB!M12<>""),TRIB!M12,"") -> 104 | O12: =IF(AND(INPUTS!$E$34=1,TRIB!M12<>""),TRIB!M12,"") -> 104 | P12: =IF(AND(INPUTS!$E$35=1,TRIB!M12<>""),TRIB!M12,"") -> 104
A13: C12 | B13: 366.75277 | C13: 517.3193 | D13: =IF(B13="","A",IF(B13>=INPUTS!$B$17,"B","A")) -> A | E13: =IF(AND(INPUTS!$E$24=1,$D13="B",TRIB!F13<>""),TRIB!F13,"") | F13: 474 | G13: 474 | H13: 474 | I13: 474 | J13: 474 | K13: 474 | L13: 474 | M13: 474 | N13: =IF(AND(INPUTS!$E$33=1,TRIB!M13<>""),TRIB!M13,"") -> 474 | O13: =IF(AND(INPUTS!$E$34=1,TRIB!M13<>""),TRIB!M13,"") -> 474 | P13: =IF(AND(INPUTS!$E$35=1,TRIB!M13<>""),TRIB!M13,"") -> 474
A14: C13 | B14: 369.2073 | C14: 565.39679 | D14: =IF(B14="","A",IF(B14>=INPUTS!$B$17,"B","A")) -> A | E14: =IF(AND(INPUTS!$E$24=1,$D14="B",TRIB!F14<>""),TRIB!F14,"") | F14: 292 | G14: 292 | H14: 292 | I14: 292 | J14: 292 | K14: 282 | L14: 282 | M14: 282 | N14: =IF(AND(INPUTS!$E$33=1,TRIB!M14<>""),TRIB!M14,"") -> 282 | O14: =IF(AND(INPUTS!$E$34=1,TRIB!M14<>""),TRIB!M14,"") -> 282 | P14: =IF(AND(INPUTS!$E$35=1,TRIB!M14<>""),TRIB!M14,"") -> 282
A15: C14 | B15: 379.78672 | C15: 488.14041 | D15: =IF(B15="","A",IF(B15>=INPUTS!$B$17,"B","A")) -> A | E15: =IF(AND(INPUTS!$E$24=1,$D15="B",TRIB!F15<>""),TRIB!F15,"") | F15: 284 | G15: 263 | H15: 263 | I15: 263 | J15: 263 | K15: 263 | L15: 263 | M15: 263 | N15: =IF(AND(INPUTS!$E$33=1,TRIB!M15<>""),TRIB!M15,"") -> 263 | O15: =IF(AND(INPUTS!$E$34=1,TRIB!M15<>""),TRIB!M15,"") -> 263 | P15: =IF(AND(INPUTS!$E$35=1,TRIB!M15<>""),TRIB!M15,"") -> 263
... A34: C33 | B34: 489.06481 | C34: 457.47643 | D34: =IF(B34="","A",IF(B34>=INPUTS!$B$17,"B","A")) -> A | E34: =IF(AND(INPUTS!$E$24=1,$D34="B",TRIB!F34<>""),TRIB!F34,"") | F34: 199 | G34: 308 | H34: 271 | I34: 271 | J34: 271 | K34: 271 | L34: 271 | M34: 271 | N34: =IF(AND(INPUTS!$E$33=1,TRIB!M34<>""),TRIB!M34,"") -> 271 | O34: =IF(AND(INPUTS!$E$34=1,TRIB!M34<>""),TRIB!M34,"") -> 271 | P34: =IF(AND(INPUTS!$E$35=1,TRIB!M34<>""),TRIB!M34,"") -> 271
A35: C34 | B35: 490.93072 | C35: 476.67579 | D35: =IF(B35="","A",IF(B35>=INPUTS!$B$17,"B","A")) -> A | E35: =IF(AND(INPUTS!$E$24=1,$D35="B",TRIB!F35<>""),TRIB!F35,"") | G35: 415 | H35: 415 | I35: 415 | J35: 415 | K35: 415 | L35: 415 | M35: 415 | N35: =IF(AND(INPUTS!$E$33=1,TRIB!M35<>""),TRIB!M35,"") -> 415 | O35: =IF(AND(INPUTS!$E$34=1,TRIB!M35<>""),TRIB!M35,"") -> 415 | P35: =IF(AND(INPUTS!$E$35=1,TRIB!M35<>""),TRIB!M35,"") -> 415
A36: C35 | B36: 496.47575 | C36: 499.58672 | D36: =IF(B36="","A",IF(B36>=INPUTS!$B$17,"B","A")) -> A | E36: =IF(AND(INPUTS!$E$24=1,$D36="B",TRIB!F36<>""),TRIB!F36,"") | F36: 612 | G36: 610 | H36: 610 | I36: 610 | J36: 610 | K36: 610 | L36: 610 | M36: 610 | N36: =IF(AND(INPUTS!$E$33=1,TRIB!M36<>""),TRIB!M36,"") -> 610 | O36: =IF(AND(INPUTS!$E$34=1,TRIB!M36<>""),TRIB!M36,"") -> 610 | P36: =IF(AND(INPUTS!$E$35=1,TRIB!M36<>""),TRIB!M36,"") -> 610
A37: C36 | B37: 498.8676 | C37: 523.1991 | D37: =IF(B37="","A",IF(B37>=INPUTS!$B$17,"B","A")) -> A | E37: =IF(AND(INPUTS!$E$24=1,$D37="B",TRIB!F37<>""),TRIB!F37,"") | F37: 276 | G37: 285 | H37: 285 | I37: 285 | J37: 285 | K37: 276 | L37: 276 | M37: 276 | N37: =IF(AND(INPUTS!$E$33=1,TRIB!M37<>""),TRIB!M37,"") -> 276 | O37: =IF(AND(INPUTS!$E$34=1,TRIB!M37<>""),TRIB!M37,"") -> 276 | P37: =IF(AND(INPUTS!$E$35=1,TRIB!M37<>""),TRIB!M37,"") -> 276
A38: C37 | B38: 501.10001 | C38: 455.78498 | D38: =IF(B38="","A",IF(B38>=INPUTS!$B$17,"B","A")) -> A | E38: =IF(AND(INPUTS!$E$24=1,$D38="B",TRIB!F38<>""),TRIB!F38,"") | F38: 158 | G38: 264 | H38: 236 | I38: 236 | J38: 236 | K38: 236 | L38: 236 | M38: 236 | N38: =IF(AND(INPUTS!$E$33=1,TRIB!M38<>""),TRIB!M38,"") -> 236 | O38: =IF(AND(INPUTS!$E$34=1,TRIB!M38<>""),TRIB!M38,"") -> 236 | P38: =IF(AND(INPUTS!$E$35=1,TRIB!M38<>""),TRIB!M38,"") -> 236
A39: C38 | B39: 501.9128 | C39: 469.05969 | D39: =IF(B39="","A",IF(B39>=INPUTS!$B$17,"B","A")) -> A | E39: =IF(AND(INPUTS!$E$24=1,$D39="B",TRIB!F39<>""),TRIB!F39,"") | F39: 357 | G39: 360 | H39: 360 | I39: 360 | J39: 360 | K39: 360 | L39: 360 | M39: 360 | N39: =IF(AND(INPUTS!$E$33=1,TRIB!M39<>""),TRIB!M39,"") -> 360 | O39: =IF(AND(INPUTS!$E$34=1,TRIB!M39<>""),TRIB!M39,"") -> 360 | P39: =IF(AND(INPUTS!$E$35=1,TRIB!M39<>""),TRIB!M39,"") -> 360
A40: C39 | B40: 512.94598 | C40: 551.27331 | D40: =IF(B40="","A",IF(B40>=INPUTS!$B$17,"B","A")) -> A | E40: =IF(AND(INPUTS!$E$24=1,$D40="B",TRIB!F40<>""),TRIB!F40,"") | F40: 112 | G40: 126 | H40: 126 | I40: 126 | J40: 126 | K40: 112 | L40: 111 | M40: 111 | N40: =IF(AND(INPUTS!$E$33=1,TRIB!M40<>""),TRIB!M40,"") -> 111 | O40: =IF(AND(INPUTS!$E$34=1,TRIB!M40<>""),TRIB!M40,"") -> 111 | P40: =IF(AND(INPUTS!$E$35=1,TRIB!M40<>""),TRIB!M40,"") -> 111
A41: C40 | B41: 512.94598 | C41: 565.46534 | D41: =IF(B41="","A",IF(B41>=INPUTS!$B$17,"B","A")) -> A | E41: =IF(AND(INPUTS!$E$24=1,$D41="B",TRIB!F41<>""),TRIB!F41,"") | F41: 116 | G41: 129 | H41: 398 | I41: 131 | J41: 130 | K41: 114 | L41: 115 | M41: 115 | N41: =IF(AND(INPUTS!$E$33=1,TRIB!M41<>""),TRIB!M41,"") -> 115 | O41: =IF(AND(INPUTS!$E$34=1,TRIB!M41<>""),TRIB!M41,"") -> 115 | P41: =IF(AND(INPUTS!$E$35=1,TRIB!M41<>""),TRIB!M41,"") -> 115
A42: C41 | B42: 517.14167 | C42: 521.43199 | D42: =IF(B42="","A",IF(B42>=INPUTS!$B$17,"B","A")) -> A | E42: =IF(AND(INPUTS!$E$24=1,$D42="B",TRIB!F42<>""),TRIB!F42,"") | F42: 192 | G42: 192 | H42: 192 | I42: 192 | J42: 192 | K42: 193 | L42: 193 | M42: 193 | N42: =IF(AND(INPUTS!$E$33=1,TRIB!M42<>""),TRIB!M42,"") -> 193 | O42: =IF(AND(INPUTS!$E$34=1,TRIB!M42<>""),TRIB!M42,"") -> 193 | P42: =IF(AND(INPUTS!$E$35=1,TRIB!M42<>""),TRIB!M42,"") -> 193
A43: C42 | B43: 519.92514 | C43: 534.54987 | D43: =IF(B43="","A",IF(B43>=INPUTS!$B$17,"B","A")) -> A | E43: =IF(AND(INPUTS!$E$24=1,$D43="B",TRIB!F43<>""),TRIB!F43,"") | F43: 169 | G43: 175 | H43: 175 | I43: 175 | J43: 175 | K43: 168 | L43: 168 | M43: 168 | N43: =IF(AND(INPUTS!$E$33=1,TRIB!M43<>""),TRIB!M43,"") -> 168 | O43: =IF(AND(INPUTS!$E$34=1,TRIB!M43<>""),TRIB!M43,"") -> 168 | P43: =IF(AND(INPUTS!$E$35=1,TRIB!M43<>""),TRIB!M43,"") -> 168
A44: C43 | B44: 522.70392 | C44: 491.49682 | D44: =IF(B44="","A",IF(B44>=INPUTS!$B$17,"B","A")) -> A | E44: =IF(AND(INPUTS!$E$24=1,$D44="B",TRIB!F44<>""),TRIB!F44,"") | F44: 485 | G44: 485 | H44: 485 | I44: 485 | J44: 486 | K44: 486 | L44: 486 | M44: 486 | N44: =IF(AND(INPUTS!$E$33=1,TRIB!M44<>""),TRIB!M44,"") -> 486 | O44: =IF(AND(INPUTS!$E$34=1,TRIB!M44<>""),TRIB!M44,"") -> 486 | P44: =IF(AND(INPUTS!$E$35=1,TRIB!M44<>""),TRIB!M44,"") -> 486
A45: C44 | B45: 525.78725 | C45: 512.24073 | D45: =IF(B45="","A",IF(B45>=INPUTS!$B$17,"B","A")) -> A | E45: =IF(AND(INPUTS!$E$24=1,$D45="B",TRIB!F45<>""),TRIB!F45,"") | F45: 224 | G45: 224 | H45: 224 | I45: 224 | J45: 224 | K45: 224 | L45: 224 | M45: 224 | N45: =IF(AND(INPUTS!$E$33=1,TRIB!M45<>""),TRIB!M45,"") -> 224 | O45: =IF(AND(INPUTS!$E$34=1,TRIB!M45<>""),TRIB!M45,"") -> 224 | P45: =IF(AND(INPUTS!$E$35=1,TRIB!M45<>""),TRIB!M45,"") -> 224
A46: C45 | B46: 526.59666 | C46: 452.93692 | D46: =IF(B46="","A",IF(B46>=INPUTS!$B$17,"B","A")) -> A | E46: =IF(AND(INPUTS!$E$24=1,$D46="B",TRIB!F46<>""),TRIB!F46,"") | F46: 139 | G46: 245 | H46: 244 | I46: 244 | J46: 244 | K46: 244 | L46: 244 | M46: 244 | N46: =IF(AND(INPUTS!$E$33=1,TRIB!M46<>""),TRIB!M46,"") -> 244 | O46: =IF(AND(INPUTS!$E$34=1,TRIB!M46<>""),TRIB!M46,"") -> 244 | P46: =IF(AND(INPUTS!$E$35=1,TRIB!M46<>""),TRIB!M46,"") -> 244
A47: C46 | B47: 526.59666 | C47: 468.19646 | D47: =IF(B47="","A",IF(B47>=INPUTS!$B$17,"B","A")) -> A | E47: =IF(AND(INPUTS!$E$24=1,$D47="B",TRIB!F47<>""),TRIB!F47,"") | F47: 474 | G47: 474 | H47: 474 | I47: 474 | J47: 475 | K47: 475 | L47: 475 | M47: 475 | N47: =IF(AND(INPUTS!$E$33=1,TRIB!M47<>""),TRIB!M47,"") -> 475 | O47: =IF(AND(INPUTS!$E$34=1,TRIB!M47<>""),TRIB!M47,"") -> 475 | P47: =IF(AND(INPUTS!$E$35=1,TRIB!M47<>""),TRIB!M47,"") -> 475
... A63: C62 | B63: 634.92099 | C63: 452.93692 | D63: =IF(B63="","A",IF(B63>=INPUTS!$B$17,"B","A")) -> B | E63: =IF(AND(INPUTS!$E$24=1,$D63="B",TRIB!F63<>""),TRIB!F63,"") -> 257 | F63: 257 | G63: 247 | H63: 342 | I63: 342 | J63: 342 | K63: 317 | L63: 89 | M63: 89 | N63: =IF(AND(INPUTS!$E$33=1,TRIB!M63<>""),TRIB!M63,"") -> 89 | O63: =IF(AND(INPUTS!$E$34=1,TRIB!M63<>""),TRIB!M63,"") -> 89 | P63: =IF(AND(INPUTS!$E$35=1,TRIB!M63<>""),TRIB!M63,"") -> 89
A64: C63 | B64: 582.98187 | C64: 1885.9394 | D64: =IF(B64="","A",IF(B64>=INPUTS!$B$17,"B","A")) -> B | E64: =IF(AND(INPUTS!$E$24=1,$D64="B",TRIB!F64<>""),TRIB!F64,"") -> 770 | F64: 770 | G64: 539 | H64: 539 | I64: 539 | J64: 553 | N64: =IF(AND(INPUTS!$E$33=1,TRIB!M64<>""),TRIB!M64,"") | O64: =IF(AND(INPUTS!$E$34=1,TRIB!M64<>""),TRIB!M64,"") | P64: =IF(AND(INPUTS!$E$35=1,TRIB!M64<>""),TRIB!M64,"")
A65: C64 | B65: 582.98187 | C65: 1919.106 | D65: =IF(B65="","A",IF(B65>=INPUTS!$B$17,"B","A")) -> B | E65: =IF(AND(INPUTS!$E$24=1,$D65="B",TRIB!F65<>""),TRIB!F65,"") -> 611 | F65: 611 | G65: 550 | H65: 551 | I65: 551 | J65: 569 | N65: =IF(AND(INPUTS!$E$33=1,TRIB!M65<>""),TRIB!M65,"") | O65: =IF(AND(INPUTS!$E$34=1,TRIB!M65<>""),TRIB!M65,"") | P65: =IF(AND(INPUTS!$E$35=1,TRIB!M65<>""),TRIB!M65,"")
A66: C65 | B66: 582.98187 | C66: 1945.7727 | D66: =IF(B66="","A",IF(B66>=INPUTS!$B$17,"B","A")) -> B | E66: =IF(AND(INPUTS!$E$24=1,$D66="B",TRIB!F66<>""),TRIB!F66,"") -> 399 | F66: 399 | G66: 339 | H66: 347 | I66: 347 | J66: 703 | N66: =IF(AND(INPUTS!$E$33=1,TRIB!M66<>""),TRIB!M66,"") | O66: =IF(AND(INPUTS!$E$34=1,TRIB!M66<>""),TRIB!M66,"") | P66: =IF(AND(INPUTS!$E$35=1,TRIB!M66<>""),TRIB!M66,"")
A67: C66 | B67: 586.05464 | C67: 1860.7733 | D67: =IF(B67="","A",IF(B67>=INPUTS!$B$17,"B","A")) -> B | E67: =IF(AND(INPUTS!$E$24=1,$D67="B",TRIB!F67<>""),TRIB!F67,"") -> 567 | F67: 567 | G67: 402 | H67: 402 | I67: 402 | J67: 396 | N67: =IF(AND(INPUTS!$E$33=1,TRIB!M67<>""),TRIB!M67,"") | O67: =IF(AND(INPUTS!$E$34=1,TRIB!M67<>""),TRIB!M67,"") | P67: =IF(AND(INPUTS!$E$35=1,TRIB!M67<>""),TRIB!M67,"")
A68: C67 | B68: 608.2213 | C68: 1888.782 | D68: =IF(B68="","A",IF(B68>=INPUTS!$B$17,"B","A")) -> B | E68: =IF(AND(INPUTS!$E$24=1,$D68="B",TRIB!F68<>""),TRIB!F68,"") -> 738 | F68: 738 | G68: 520 | H68: 520 | I68: 520 | J68: 770 | N68: =IF(AND(INPUTS!$E$33=1,TRIB!M68<>""),TRIB!M68,"") | O68: =IF(AND(INPUTS!$E$34=1,TRIB!M68<>""),TRIB!M68,"") | P68: =IF(AND(INPUTS!$E$35=1,TRIB!M68<>""),TRIB!M68,"")
A69: C68 | B69: 608.2213 | C69: 1919.782 | D69: =IF(B69="","A",IF(B69>=INPUTS!$B$17,"B","A")) -> B | E69: =IF(AND(INPUTS!$E$24=1,$D69="B",TRIB!F69<>""),TRIB!F69,"") -> 750 | F69: 750 | G69: 555 | H69: 555 | I69: 555 | J69: 757 | N69: =IF(AND(INPUTS!$E$33=1,TRIB!M69<>""),TRIB!M69,"") | O69: =IF(AND(INPUTS!$E$34=1,TRIB!M69<>""),TRIB!M69,"") | P69: =IF(AND(INPUTS!$E$35=1,TRIB!M69<>""),TRIB!M69,"")
A70: C69 | B70: 608.2213 | C70: 1946.9477 | D70: =IF(B70="","A",IF(B70>=INPUTS!$B$17,"B","A")) -> B | E70: =IF(AND(INPUTS!$E$24=1,$D70="B",TRIB!F70<>""),TRIB!F70,"") -> 373 | F70: 373 | G70: 373 | H70: 373 | I70: 373 | J70: 672 | N70: =IF(AND(INPUTS!$E$33=1,TRIB!M70<>""),TRIB!M70,"") | O70: =IF(AND(INPUTS!$E$34=1,TRIB!M70<>""),TRIB!M70,"") | P70: =IF(AND(INPUTS!$E$35=1,TRIB!M70<>""),TRIB!M70,"")
A71: C70 | B71: 612.7213 | C71: 1860.7733 | D71: =IF(B71="","A",IF(B71>=INPUTS!$B$17,"B","A")) -> B | E71: =IF(AND(INPUTS!$E$24=1,$D71="B",TRIB!F71<>""),TRIB!F71,"") -> 548 | F71: 548 | G71: 508 | H71: 508 | I71: 508 | J71: 503 | N71: =IF(AND(INPUTS!$E$33=1,TRIB!M71<>""),TRIB!M71,"") | O71: =IF(AND(INPUTS!$E$34=1,TRIB!M71<>""),TRIB!M71,"") | P71: =IF(AND(INPUTS!$E$35=1,TRIB!M71<>""),TRIB!M71,"")
A72: C71 | B72: 634.88797 | C72: 1860.7733 | D72: =IF(B72="","A",IF(B72>=INPUTS!$B$17,"B","A")) -> B | E72: =IF(AND(INPUTS!$E$24=1,$D72="B",TRIB!F72<>""),TRIB!F72,"") -> 515 | F72: 515 | G72: 506 | H72: 506 | I72: 506 | J72: 500 | N72: =IF(AND(INPUTS!$E$33=1,TRIB!M72<>""),TRIB!M72,"") | O72: =IF(AND(INPUTS!$E$34=1,TRIB!M72<>""),TRIB!M72,"") | P72: =IF(AND(INPUTS!$E$35=1,TRIB!M72<>""),TRIB!M72,"")
A73: C72 | B73: 634.88797 | C73: 1888.782 | D73: =IF(B73="","A",IF(B73>=INPUTS!$B$17,"B","A")) -> B | E73: =IF(AND(INPUTS!$E$24=1,$D73="B",TRIB!F73<>""),TRIB!F73,"") -> 75 | F73: 75 | G73: 501 | H73: 501 | I73: 501 | J73: 558 | N73: =IF(AND(INPUTS!$E$33=1,TRIB!M73<>""),TRIB!M73,"") | O73: =IF(AND(INPUTS!$E$34=1,TRIB!M73<>""),TRIB!M73,"") | P73: =IF(AND(INPUTS!$E$35=1,TRIB!M73<>""),TRIB!M73,"")
...

Sheet KLL
A1: Column | B1: x (ft) | C1: y (ft) | D1: Section | E1: ROOF | F1: 11 | G1: 10 | H1: 9 | I1: 8 | J1: 7 | K1: 6 | L1: 5 | M1: 4 | N1: 3 | O1: 2 | P1: 1 | R1: Live-load element factor per column per level from the engine (4 interior, 3 edge, 2 corner). Blank = engine gave none; INPUTS default applies.
A2: =TRIB!A2 -> C1 | B2: =TRIB!B2 -> 283.70052 | C2: =TRIB!C2 -> 569.16697 | D2: =TRIB!D2 -> A | E2: =IF(KLL!F2="","",KLL!F2) -> 2 | F2: 2 | G2: 2 | H2: 2 | I2: 2 | J2: 2 | K2: 2 | L2: 2 | M2: 2 | N2: =IF(KLL!M2="","",KLL!M2) -> 2 | O2: =IF(KLL!M2="","",KLL!M2) -> 2 | P2: =IF(KLL!M2="","",KLL!M2) -> 2
A3: =TRIB!A3 -> C2 | B3: =TRIB!B3 -> 283.56914 | C3: =TRIB!C3 -> 554.06436 | D3: =TRIB!D3 -> A | E3: =IF(KLL!F3="","",KLL!F3) | G3: 2 | H3: 2 | I3: 2 | J3: 2 | K3: 2 | L3: 2 | M3: 2 | N3: =IF(KLL!M3="","",KLL!M3) -> 2 | O3: =IF(KLL!M3="","",KLL!M3) -> 2 | P3: =IF(KLL!M3="","",KLL!M3) -> 2
A4: =TRIB!A4 -> C3 | B4: =TRIB!B4 -> 302.32736 | C4: =TRIB!C4 -> 538.83473 | D4: =TRIB!D4 -> A | E4: =IF(KLL!F4="","",KLL!F4) -> 2 | F4: 2 | G4: 2 | H4: 2 | I4: 2 | J4: 2 | K4: 3 | L4: 3 | M4: 3 | N4: =IF(KLL!M4="","",KLL!M4) -> 3 | O4: =IF(KLL!M4="","",KLL!M4) -> 3 | P4: =IF(KLL!M4="","",KLL!M4) -> 3
A5: =TRIB!A5 -> C4 | B5: =TRIB!B5 -> 301.5302 | C5: =TRIB!C5 -> 560.06227 | D5: =TRIB!D5 -> A | E5: =IF(KLL!F5="","",KLL!F5) -> 2 | F5: 2 | G5: 2 | H5: 2 | I5: 2 | J5: 2 | K5: 3 | L5: 3 | M5: 3 | N5: =IF(KLL!M5="","",KLL!M5) -> 3 | O5: =IF(KLL!M5="","",KLL!M5) -> 3 | P5: =IF(KLL!M5="","",KLL!M5) -> 3
A6: =TRIB!A6 -> C5 | B6: =TRIB!B6 -> 311.63942 | C6: =TRIB!C6 -> 569.16697 | D6: =TRIB!D6 -> A | E6: =IF(KLL!F6="","",KLL!F6) -> 2 | F6: 2 | G6: 2 | H6: 2 | I6: 2 | J6: 2 | K6: 3 | L6: 3 | M6: 3 | N6: =IF(KLL!M6="","",KLL!M6) -> 3 | O6: =IF(KLL!M6="","",KLL!M6) -> 3 | P6: =IF(KLL!M6="","",KLL!M6) -> 3
A7: =TRIB!A7 -> C6 | B7: =TRIB!B7 -> 313.93295 | C7: =TRIB!C7 -> 553.64886 | D7: =TRIB!D7 -> A | E7: =IF(KLL!F7="","",KLL!F7) -> 2 | F7: 2 | G7: 2 | H7: 2 | I7: 2 | J7: 2 | K7: 3 | L7: 3 | M7: 3 | N7: =IF(KLL!M7="","",KLL!M7) -> 3 | O7: =IF(KLL!M7="","",KLL!M7) -> 3 | P7: =IF(KLL!M7="","",KLL!M7) -> 3
A8: =TRIB!A8 -> C7 | B8: =TRIB!B8 -> 336.33509 | C8: =TRIB!C8 -> 514.66264 | D8: =TRIB!D8 -> A | E8: =IF(KLL!F8="","",KLL!F8) -> 3 | F8: 3 | G8: 3 | H8: 3 | I8: 3 | J8: 3 | K8: 3 | L8: 3 | M8: 3 | N8: =IF(KLL!M8="","",KLL!M8) -> 3 | O8: =IF(KLL!M8="","",KLL!M8) -> 3 | P8: =IF(KLL!M8="","",KLL!M8) -> 3
A9: =TRIB!A9 -> C8 | B9: =TRIB!B9 -> 346.65209 | C9: =TRIB!C9 -> 529.37224 | D9: =TRIB!D9 -> A | E9: =IF(KLL!F9="","",KLL!F9) -> 3 | F9: 3 | G9: 3 | H9: 3 | I9: 3 | J9: 3 | K9: 4 | L9: 4 | M9: 4 | N9: =IF(KLL!M9="","",KLL!M9) -> 4 | O9: =IF(KLL!M9="","",KLL!M9) -> 4 | P9: =IF(KLL!M9="","",KLL!M9) -> 4
A10: =TRIB!A10 -> C9 | B10: =TRIB!B10 -> 356.10812 | C10: =TRIB!C10 -> 546.09305 | D10: =TRIB!D10 -> A | E10: =IF(KLL!F10="","",KLL!F10) -> 3 | F10: 3 | G10: 3 | H10: 3 | I10: 3 | J10: 3 | K10: 4 | L10: 4 | M10: 4 | N10: =IF(KLL!M10="","",KLL!M10) -> 4 | O10: =IF(KLL!M10="","",KLL!M10) -> 4 | P10: =IF(KLL!M10="","",KLL!M10) -> 4
A11: =TRIB!A11 -> C10 | B11: =TRIB!B11 -> 357.42596 | C11: =TRIB!C11 -> 500.43849 | D11: =TRIB!D11 -> A | E11: =IF(KLL!F11="","",KLL!F11) -> 3 | F11: 3 | G11: 3 | H11: 3 | I11: 3 | J11: 3 | K11: 3 | L11: 3 | M11: 3 | N11: =IF(KLL!M11="","",KLL!M11) -> 3 | O11: =IF(KLL!M11="","",KLL!M11) -> 3 | P11: =IF(KLL!M11="","",KLL!M11) -> 3
A12: =TRIB!A12 -> C11 | B12: =TRIB!B12 -> 363.12676 | C12: =TRIB!C12 -> 569.16697 | D12: =TRIB!D12 -> A | E12: =IF(KLL!F12="","",KLL!F12) -> 3 | F12: 3 | G12: 3 | H12: 3 | I12: 3 | J12: 3 | K12: 3 | L12: 3 | M12: 3 | N12: =IF(KLL!M12="","",KLL!M12) -> 3 | O12: =IF(KLL!M12="","",KLL!M12) -> 3 | P12: =IF(KLL!M12="","",KLL!M12) -> 3
A13: =TRIB!A13 -> C12 | B13: =TRIB!B13 -> 366.75277 | C13: =TRIB!C13 -> 517.3193 | D13: =TRIB!D13 -> A | E13: =IF(KLL!F13="","",KLL!F13) -> 3 | F13: 3 | G13: 3 | H13: 3 | I13: 3 | J13: 3 | K13: 4 | L13: 4 | M13: 4 | N13: =IF(KLL!M13="","",KLL!M13) -> 4 | O13: =IF(KLL!M13="","",KLL!M13) -> 4 | P13: =IF(KLL!M13="","",KLL!M13) -> 4
A14: =TRIB!A14 -> C13 | B14: =TRIB!B14 -> 369.2073 | C14: =TRIB!C14 -> 565.39679 | D14: =TRIB!D14 -> A | E14: =IF(KLL!F14="","",KLL!F14) -> 3 | F14: 3 | G14: 3 | H14: 3 | I14: 3 | J14: 3 | K14: 3 | L14: 3 | M14: 3 | N14: =IF(KLL!M14="","",KLL!M14) -> 3 | O14: =IF(KLL!M14="","",KLL!M14) -> 3 | P14: =IF(KLL!M14="","",KLL!M14) -> 3
A15: =TRIB!A15 -> C14 | B15: =TRIB!B15 -> 379.78672 | C15: =TRIB!C15 -> 488.14041 | D15: =TRIB!D15 -> A | E15: =IF(KLL!F15="","",KLL!F15) -> 3 | F15: 3 | G15: 3 | H15: 3 | I15: 3 | J15: 3 | K15: 3 | L15: 3 | M15: 3 | N15: =IF(KLL!M15="","",KLL!M15) -> 3 | O15: =IF(KLL!M15="","",KLL!M15) -> 3 | P15: =IF(KLL!M15="","",KLL!M15) -> 3
... A34: =TRIB!A34 -> C33 | B34: =TRIB!B34 -> 489.06481 | C34: =TRIB!C34 -> 457.47643 | D34: =TRIB!D34 -> A | E34: =IF(KLL!F34="","",KLL!F34) -> 3 | F34: 3 | G34: 3 | H34: 3 | I34: 3 | J34: 3 | K34: 3 | L34: 3 | M34: 3 | N34: =IF(KLL!M34="","",KLL!M34) -> 3 | O34: =IF(KLL!M34="","",KLL!M34) -> 3 | P34: =IF(KLL!M34="","",KLL!M34) -> 3
A35: =TRIB!A35 -> C34 | B35: =TRIB!B35 -> 490.93072 | C35: =TRIB!C35 -> 476.67579 | D35: =TRIB!D35 -> A | E35: =IF(KLL!F35="","",KLL!F35) | G35: 3 | H35: 3 | I35: 3 | J35: 3 | K35: 4 | L35: 4 | M35: 4 | N35: =IF(KLL!M35="","",KLL!M35) -> 4 | O35: =IF(KLL!M35="","",KLL!M35) -> 4 | P35: =IF(KLL!M35="","",KLL!M35) -> 4
A36: =TRIB!A36 -> C35 | B36: =TRIB!B36 -> 496.47575 | C36: =TRIB!C36 -> 499.58672 | D36: =TRIB!D36 -> A | E36: =IF(KLL!F36="","",KLL!F36) -> 3 | F36: 3 | G36: 3 | H36: 3 | I36: 3 | J36: 3 | K36: 4 | L36: 4 | M36: 4 | N36: =IF(KLL!M36="","",KLL!M36) -> 4 | O36: =IF(KLL!M36="","",KLL!M36) -> 4 | P36: =IF(KLL!M36="","",KLL!M36) -> 4
A37: =TRIB!A37 -> C36 | B37: =TRIB!B37 -> 498.8676 | C37: =TRIB!C37 -> 523.1991 | D37: =TRIB!D37 -> A | E37: =IF(KLL!F37="","",KLL!F37) -> 3 | F37: 3 | G37: 3 | H37: 3 | I37: 3 | J37: 3 | K37: 3 | L37: 3 | M37: 3 | N37: =IF(KLL!M37="","",KLL!M37) -> 3 | O37: =IF(KLL!M37="","",KLL!M37) -> 3 | P37: =IF(KLL!M37="","",KLL!M37) -> 3
A38: =TRIB!A38 -> C37 | B38: =TRIB!B38 -> 501.10001 | C38: =TRIB!C38 -> 455.78498 | D38: =TRIB!D38 -> A | E38: =IF(KLL!F38="","",KLL!F38) -> 3 | F38: 3 | G38: 3 | H38: 3 | I38: 3 | J38: 3 | K38: 3 | L38: 3 | M38: 3 | N38: =IF(KLL!M38="","",KLL!M38) -> 3 | O38: =IF(KLL!M38="","",KLL!M38) -> 3 | P38: =IF(KLL!M38="","",KLL!M38) -> 3
A39: =TRIB!A39 -> C38 | B39: =TRIB!B39 -> 501.9128 | C39: =TRIB!C39 -> 469.05969 | D39: =TRIB!D39 -> A | E39: =IF(KLL!F39="","",KLL!F39) -> 3 | F39: 3 | G39: 3 | H39: 3 | I39: 3 | J39: 3 | K39: 3 | L39: 3 | M39: 3 | N39: =IF(KLL!M39="","",KLL!M39) -> 3 | O39: =IF(KLL!M39="","",KLL!M39) -> 3 | P39: =IF(KLL!M39="","",KLL!M39) -> 3
A40: =TRIB!A40 -> C39 | B40: =TRIB!B40 -> 512.94598 | C40: =TRIB!C40 -> 551.27331 | D40: =TRIB!D40 -> A | E40: =IF(KLL!F40="","",KLL!F40) -> 3 | F40: 3 | G40: 3 | H40: 3 | I40: 3 | J40: 3 | K40: 3 | L40: 3 | M40: 3 | N40: =IF(KLL!M40="","",KLL!M40) -> 3 | O40: =IF(KLL!M40="","",KLL!M40) -> 3 | P40: =IF(KLL!M40="","",KLL!M40) -> 3
A41: =TRIB!A41 -> C40 | B41: =TRIB!B41 -> 512.94598 | C41: =TRIB!C41 -> 565.46534 | D41: =TRIB!D41 -> A | E41: =IF(KLL!F41="","",KLL!F41) -> 3 | F41: 3 | G41: 3 | H41: 3 | I41: 3 | J41: 3 | K41: 3 | L41: 3 | M41: 3 | N41: =IF(KLL!M41="","",KLL!M41) -> 3 | O41: =IF(KLL!M41="","",KLL!M41) -> 3 | P41: =IF(KLL!M41="","",KLL!M41) -> 3
A42: =TRIB!A42 -> C41 | B42: =TRIB!B42 -> 517.14167 | C42: =TRIB!C42 -> 521.43199 | D42: =TRIB!D42 -> A | E42: =IF(KLL!F42="","",KLL!F42) -> 3 | F42: 3 | G42: 3 | H42: 3 | I42: 3 | J42: 3 | K42: 3 | L42: 3 | M42: 3 | N42: =IF(KLL!M42="","",KLL!M42) -> 3 | O42: =IF(KLL!M42="","",KLL!M42) -> 3 | P42: =IF(KLL!M42="","",KLL!M42) -> 3
A43: =TRIB!A43 -> C42 | B43: =TRIB!B43 -> 519.92514 | C43: =TRIB!C43 -> 534.54987 | D43: =TRIB!D43 -> A | E43: =IF(KLL!F43="","",KLL!F43) -> 3 | F43: 3 | G43: 3 | H43: 3 | I43: 3 | J43: 3 | K43: 3 | L43: 3 | M43: 3 | N43: =IF(KLL!M43="","",KLL!M43) -> 3 | O43: =IF(KLL!M43="","",KLL!M43) -> 3 | P43: =IF(KLL!M43="","",KLL!M43) -> 3
A44: =TRIB!A44 -> C43 | B44: =TRIB!B44 -> 522.70392 | C44: =TRIB!C44 -> 491.49682 | D44: =TRIB!D44 -> A | E44: =IF(KLL!F44="","",KLL!F44) -> 3 | F44: 3 | G44: 3 | H44: 3 | I44: 3 | J44: 3 | K44: 4 | L44: 4 | M44: 4 | N44: =IF(KLL!M44="","",KLL!M44) -> 4 | O44: =IF(KLL!M44="","",KLL!M44) -> 4 | P44: =IF(KLL!M44="","",KLL!M44) -> 4
A45: =TRIB!A45 -> C44 | B45: =TRIB!B45 -> 525.78725 | C45: =TRIB!C45 -> 512.24073 | D45: =TRIB!D45 -> A | E45: =IF(KLL!F45="","",KLL!F45) -> 3 | F45: 3 | G45: 3 | H45: 3 | I45: 3 | J45: 3 | K45: 3 | L45: 3 | M45: 3 | N45: =IF(KLL!M45="","",KLL!M45) -> 3 | O45: =IF(KLL!M45="","",KLL!M45) -> 3 | P45: =IF(KLL!M45="","",KLL!M45) -> 3
A46: =TRIB!A46 -> C45 | B46: =TRIB!B46 -> 526.59666 | C46: =TRIB!C46 -> 452.93692 | D46: =TRIB!D46 -> A | E46: =IF(KLL!F46="","",KLL!F46) -> 3 | F46: 3 | G46: 3 | H46: 3 | I46: 3 | J46: 3 | K46: 3 | L46: 3 | M46: 3 | N46: =IF(KLL!M46="","",KLL!M46) -> 3 | O46: =IF(KLL!M46="","",KLL!M46) -> 3 | P46: =IF(KLL!M46="","",KLL!M46) -> 3
A47: =TRIB!A47 -> C46 | B47: =TRIB!B47 -> 526.59666 | C47: =TRIB!C47 -> 468.19646 | D47: =TRIB!D47 -> A | E47: =IF(KLL!F47="","",KLL!F47) -> 3 | F47: 3 | G47: 3 | H47: 3 | I47: 3 | J47: 3 | K47: 4 | L47: 4 | M47: 4 | N47: =IF(KLL!M47="","",KLL!M47) -> 4 | O47: =IF(KLL!M47="","",KLL!M47) -> 4 | P47: =IF(KLL!M47="","",KLL!M47) -> 4
... A63: =TRIB!A63 -> C62 | B63: =TRIB!B63 -> 634.92099 | C63: =TRIB!C63 -> 452.93692 | D63: =TRIB!D63 -> B | E63: =IF(KLL!F63="","",KLL!F63) -> 3 | F63: 3 | G63: 3 | H63: 3 | I63: 3 | J63: 3 | K63: 3 | L63: 2 | M63: 2 | N63: =IF(KLL!M63="","",KLL!M63) -> 2 | O63: =IF(KLL!M63="","",KLL!M63) -> 2 | P63: =IF(KLL!M63="","",KLL!M63) -> 2
A64: =TRIB!A64 -> C63 | B64: =TRIB!B64 -> 582.98187 | C64: =TRIB!C64 -> 1885.9394 | D64: =TRIB!D64 -> B | E64: =IF(KLL!F64="","",KLL!F64) -> 4 | F64: 4 | G64: 4 | H64: 4 | I64: 3 | J64: 3 | N64: =IF(KLL!M64="","",KLL!M64) | O64: =IF(KLL!M64="","",KLL!M64) | P64: =IF(KLL!M64="","",KLL!M64)
A65: =TRIB!A65 -> C64 | B65: =TRIB!B65 -> 582.98187 | C65: =TRIB!C65 -> 1919.106 | D65: =TRIB!D65 -> B | E65: =IF(KLL!F65="","",KLL!F65) -> 3 | F65: 3 | G65: 3 | H65: 3 | I65: 3 | J65: 3 | N65: =IF(KLL!M65="","",KLL!M65) | O65: =IF(KLL!M65="","",KLL!M65) | P65: =IF(KLL!M65="","",KLL!M65)
A66: =TRIB!A66 -> C65 | B66: =TRIB!B66 -> 582.98187 | C66: =TRIB!C66 -> 1945.7727 | D66: =TRIB!D66 -> B | E66: =IF(KLL!F66="","",KLL!F66) -> 3 | F66: 3 | G66: 3 | H66: 3 | I66: 3 | J66: 3 | N66: =IF(KLL!M66="","",KLL!M66) | O66: =IF(KLL!M66="","",KLL!M66) | P66: =IF(KLL!M66="","",KLL!M66)
A67: =TRIB!A67 -> C66 | B67: =TRIB!B67 -> 586.05464 | C67: =TRIB!C67 -> 1860.7733 | D67: =TRIB!D67 -> B | E67: =IF(KLL!F67="","",KLL!F67) -> 3 | F67: 3 | G67: 3 | H67: 3 | I67: 3 | J67: 3 | N67: =IF(KLL!M67="","",KLL!M67) | O67: =IF(KLL!M67="","",KLL!M67) | P67: =IF(KLL!M67="","",KLL!M67)
A68: =TRIB!A68 -> C67 | B68: =TRIB!B68 -> 608.2213 | C68: =TRIB!C68 -> 1888.782 | D68: =TRIB!D68 -> B | E68: =IF(KLL!F68="","",KLL!F68) -> 4 | F68: 4 | G68: 4 | H68: 4 | I68: 4 | J68: 4 | N68: =IF(KLL!M68="","",KLL!M68) | O68: =IF(KLL!M68="","",KLL!M68) | P68: =IF(KLL!M68="","",KLL!M68)
A69: =TRIB!A69 -> C68 | B69: =TRIB!B69 -> 608.2213 | C69: =TRIB!C69 -> 1919.782 | D69: =TRIB!D69 -> B | E69: =IF(KLL!F69="","",KLL!F69) -> 3 | F69: 3 | G69: 3 | H69: 3 | I69: 3 | J69: 3 | N69: =IF(KLL!M69="","",KLL!M69) | O69: =IF(KLL!M69="","",KLL!M69) | P69: =IF(KLL!M69="","",KLL!M69)
A70: =TRIB!A70 -> C69 | B70: =TRIB!B70 -> 608.2213 | C70: =TRIB!C70 -> 1946.9477 | D70: =TRIB!D70 -> B | E70: =IF(KLL!F70="","",KLL!F70) -> 3 | F70: 3 | G70: 3 | H70: 3 | I70: 3 | J70: 3 | N70: =IF(KLL!M70="","",KLL!M70) | O70: =IF(KLL!M70="","",KLL!M70) | P70: =IF(KLL!M70="","",KLL!M70)
A71: =TRIB!A71 -> C70 | B71: =TRIB!B71 -> 612.7213 | C71: =TRIB!C71 -> 1860.7733 | D71: =TRIB!D71 -> B | E71: =IF(KLL!F71="","",KLL!F71) -> 3 | F71: 3 | G71: 3 | H71: 3 | I71: 3 | J71: 3 | N71: =IF(KLL!M71="","",KLL!M71) | O71: =IF(KLL!M71="","",KLL!M71) | P71: =IF(KLL!M71="","",KLL!M71)
A72: =TRIB!A72 -> C71 | B72: =TRIB!B72 -> 634.88797 | C72: =TRIB!C72 -> 1860.7733 | D72: =TRIB!D72 -> B | E72: =IF(KLL!F72="","",KLL!F72) -> 3 | F72: 3 | G72: 3 | H72: 3 | I72: 3 | J72: 3 | N72: =IF(KLL!M72="","",KLL!M72) | O72: =IF(KLL!M72="","",KLL!M72) | P72: =IF(KLL!M72="","",KLL!M72)
A73: =TRIB!A73 -> C72 | B73: =TRIB!B73 -> 634.88797 | C73: =TRIB!C73 -> 1888.782 | D73: =TRIB!D73 -> B | E73: =IF(KLL!F73="","",KLL!F73) -> 4 | F73: 4 | G73: 4 | H73: 4 | I73: 3 | J73: 3 | N73: =IF(KLL!M73="","",KLL!M73) | O73: =IF(KLL!M73="","",KLL!M73) | P73: =IF(KLL!M73="","",KLL!M73)
...

Sheet FACADE
A1: Column | B1: x (ft) | C1: y (ft) | D1: Section | E1: ROOF | F1: 11 | G1: 10 | H1: 9 | I1: 8 | J1: 7 | K1: 6 | L1: 5 | M1: 4 | N1: 3 | O1: 2 | P1: 1 | R1: Facade length (ft) attributed to each column per level by the engine's perimeter attribution.
A2: =TRIB!A2 -> C1 | B2: =TRIB!B2 -> 283.70052 | C2: =TRIB!C2 -> 569.16697 | D2: =TRIB!D2 -> A | F2: 49 | G2: 31 | H2: 32 | I2: 32 | J2: 32 | K2: 29 | L2: 29 | M2: 29 | N2: =IF(FACADE!M2="","",FACADE!M2) -> 29 | O2: =IF(FACADE!M2="","",FACADE!M2) -> 29 | P2: =IF(FACADE!M2="","",FACADE!M2) -> 29
A3: =TRIB!A3 -> C2 | B3: =TRIB!B3 -> 283.56914 | C3: =TRIB!C3 -> 554.06436 | D3: =TRIB!D3 -> A | G3: 29 | H3: 29 | I3: 29 | J3: 29 | K3: 29 | L3: 29 | M3: 29 | N3: =IF(FACADE!M3="","",FACADE!M3) -> 29 | O3: =IF(FACADE!M3="","",FACADE!M3) -> 29 | P3: =IF(FACADE!M3="","",FACADE!M3) -> 29
A4: =TRIB!A4 -> C3 | B4: =TRIB!B4 -> 302.32736 | C4: =TRIB!C4 -> 538.83473 | D4: =TRIB!D4 -> A | F4: 32 | G4: 24 | H4: 25 | I4: 25 | J4: 25 | K4: 25 | L4: 25 | M4: 25 | N4: =IF(FACADE!M4="","",FACADE!M4) -> 25 | O4: =IF(FACADE!M4="","",FACADE!M4) -> 25 | P4: =IF(FACADE!M4="","",FACADE!M4) -> 25
A5: =TRIB!A5 -> C4 | B5: =TRIB!B5 -> 301.5302 | C5: =TRIB!C5 -> 560.06227 | D5: =TRIB!D5 -> A | F5: 6 | G5: 6 | H5: 6 | I5: 6 | J5: 6 | K5: 6 | L5: 6 | M5: 6 | N5: =IF(FACADE!M5="","",FACADE!M5) -> 6 | O5: =IF(FACADE!M5="","",FACADE!M5) -> 6 | P5: =IF(FACADE!M5="","",FACADE!M5) -> 6
A6: =TRIB!A6 -> C5 | B6: =TRIB!B6 -> 311.63942 | C6: =TRIB!C6 -> 569.16697 | D6: =TRIB!D6 -> A | F6: 17 | G6: 17 | H6: 17 | I6: 17 | J6: 17 | K6: 17 | L6: 17 | M6: 17 | N6: =IF(FACADE!M6="","",FACADE!M6) -> 17 | O6: =IF(FACADE!M6="","",FACADE!M6) -> 17 | P6: =IF(FACADE!M6="","",FACADE!M6) -> 17
A7: =TRIB!A7 -> C6 | B7: =TRIB!B7 -> 313.93295 | C7: =TRIB!C7 -> 553.64886 | D7: =TRIB!D7 -> A | N7: =IF(FACADE!M7="","",FACADE!M7) | O7: =IF(FACADE!M7="","",FACADE!M7) | P7: =IF(FACADE!M7="","",FACADE!M7)
A8: =TRIB!A8 -> C7 | B8: =TRIB!B8 -> 336.33509 | C8: =TRIB!C8 -> 514.66264 | D8: =TRIB!D8 -> A | F8: 29 | G8: 30 | H8: 30 | I8: 30 | J8: 29 | K8: 30 | L8: 30 | M8: 30 | N8: =IF(FACADE!M8="","",FACADE!M8) -> 30 | O8: =IF(FACADE!M8="","",FACADE!M8) -> 30 | P8: =IF(FACADE!M8="","",FACADE!M8) -> 30
A9: =TRIB!A9 -> C8 | B9: =TRIB!B9 -> 346.65209 | C9: =TRIB!C9 -> 529.37224 | D9: =TRIB!D9 -> A | N9: =IF(FACADE!M9="","",FACADE!M9) | O9: =IF(FACADE!M9="","",FACADE!M9) | P9: =IF(FACADE!M9="","",FACADE!M9)
A10: =TRIB!A10 -> C9 | B10: =TRIB!B10 -> 356.10812 | C10: =TRIB!C10 -> 546.09305 | D10: =TRIB!D10 -> A | N10: =IF(FACADE!M10="","",FACADE!M10) | O10: =IF(FACADE!M10="","",FACADE!M10) | P10: =IF(FACADE!M10="","",FACADE!M10)
A11: =TRIB!A11 -> C10 | B11: =TRIB!B11 -> 357.42596 | C11: =TRIB!C11 -> 500.43849 | D11: =TRIB!D11 -> A | F11: 31 | G11: 29 | H11: 29 | I11: 29 | J11: 29 | K11: 29 | L11: 29 | M11: 29 | N11: =IF(FACADE!M11="","",FACADE!M11) -> 29 | O11: =IF(FACADE!M11="","",FACADE!M11) -> 29 | P11: =IF(FACADE!M11="","",FACADE!M11) -> 29
A12: =TRIB!A12 -> C11 | B12: =TRIB!B12 -> 363.12676 | C12: =TRIB!C12 -> 569.16697 | D12: =TRIB!D12 -> A | F12: 16 | G12: 16 | H12: 15 | I12: 15 | J12: 15 | K12: 15 | L12: 15 | M12: 15 | N12: =IF(FACADE!M12="","",FACADE!M12) -> 15 | O12: =IF(FACADE!M12="","",FACADE!M12) -> 15 | P12: =IF(FACADE!M12="","",FACADE!M12) -> 15
A13: =TRIB!A13 -> C12 | B13: =TRIB!B13 -> 366.75277 | C13: =TRIB!C13 -> 517.3193 | D13: =TRIB!D13 -> A | N13: =IF(FACADE!M13="","",FACADE!M13) | O13: =IF(FACADE!M13="","",FACADE!M13) | P13: =IF(FACADE!M13="","",FACADE!M13)
A14: =TRIB!A14 -> C13 | B14: =TRIB!B14 -> 369.2073 | C14: =TRIB!C14 -> 565.39679 | D14: =TRIB!D14 -> A | F14: 16 | G14: 16 | H14: 16 | I14: 16 | J14: 16 | K14: 18 | L14: 18 | M14: 18 | N14: =IF(FACADE!M14="","",FACADE!M14) -> 18 | O14: =IF(FACADE!M14="","",FACADE!M14) -> 18 | P14: =IF(FACADE!M14="","",FACADE!M14) -> 18
